Workbook

Sheet Geral
D2: Janeiro | E2: fevereiro | F2: março | G2: abril | H2: maio | I2: junho | J2: julho | K2: agosto | L2: setembro | M2: outubro | N2: novembro | O2: dezembro
D3: ='Vendas e Engenharia'!G67 -> 30191.66 | E3: ='Vendas e Engenharia'!H67 -> 30059.73 | F3: ='Vendas e Engenharia'!I67 -> 41846.95 | G3: ='Vendas e Engenharia'!J67 -> 40111.45 | H3: ='Vendas e Engenharia'!K67 -> 43675.7 | I3: ='Vendas e Engenharia'!L67 -> 41043.7 | J3: ='Vendas e Engenharia'!M67 -> 44625.7 | K3: ='Vendas e Engenharia'!N67 -> 45186.3 | ... O3: ='Vendas e Engenharia'!R67 -> 0
D4: =Hardware!F61 -> 15075 | E4: =Hardware!G61 -> 13200 | F4: =Hardware!H61 -> 13800 | G4: =Hardware!I61 -> 13321 | H4: =Hardware!J61 -> 10821 | I4: =Hardware!K61 -> 13321 | J4: =Hardware!L61 -> 14471 | K4: =Hardware!M61 -> 14471 | ... O4: =Hardware!Q61 -> 0
D5: =Software!D10 -> 7998.4 | E5: =Software!E10 -> 8000 | F5: =Software!F10 -> 7000 | G5: =Software!G10 -> 7000 | H5: =Software!H10 -> 7000 | I5: =Software!I10 -> 7000 | J5: =Software!J10 -> 7000 | K5: =Software!K10 -> 7000 | ... O5: =Software!O10 -> 0
E6: 970 | F6: 970 | I6: 1000
D7: =900 -> 900 | E7: 900 | F7: 900 | I7: 900
D8: =SUM(D3:D7) -> 54165.06 | E8: =SUM(E3:E7)-'Vendas e Engenharia'!H33 -> 47264.23 | F8: =SUM(F3:F7) -> 64516.95 | G8: =SUM(G3:G7) -> 60432.45 | H8: =SUM(H3:H7) -> 61496.7 | I8: =SUM(I3:I7)-1400 -> 61864.7 | J8: =SUM(J3:J7) -> 66096.7 | K8: =SUM(K3:K7) -> 66657.3 | L8: =SUM(L3:L7) -> 0 | M8: =SUM(M3:M7) -> 0 | N8: =SUM(N3:N7) -> 0 | O8: =SUM(O3:O7) -> 0
E12: Sócio Adm | F12: Fernando | G12: ='Vendas e Engenharia'!N3 -> 5000 | H12: ok | J12: Comissões que vem de obras
E13: Sócio | F13: Gabriel | G13: ='Vendas e Engenharia'!N13 -> 11300.7 | H13: =G13-1621 -> 9679.7 | J13: =SUM('Vendas e Engenharia'!J38,'Vendas e Engenharia'!J25,'Vendas e Engenharia'!J15) -> 3010
E14: Sócio | F14: Jonildo | G14: ='Vendas e Engenharia'!N23 -> 7500 | H14: ok
E15: Mei | F15: Igor | G15: ='Vendas e Engenharia'!N33 -> 8868.6 | H15: ok
E16: Sócio Adm | F16: Belo | G16: =Hardware!M6 -> 4500 | H16: ok | J16: =5000-1621 -> 3379
E17: Sócio | F17: Adryan | G17: =Hardware!M17 -> 1621 | H17: ok
E18: Sócio | F18: Tiago | G18: =Hardware!M28 -> 600 | H18: ok | J18: =#REF!-J16-1621 -> #REF!
E19: Mei | F19: Flavio | G19: =Hardware!M39 -> 5100 | H19: ok
E20: Mei | F20: Diogo | G20: =Hardware!M50 -> 2650 | H20: ok
E21: Sócio Adm | F21: Dec | G21: =Software!K4 -> 4500 | H21: ok
E22: Mei | F22: Evera | G22: 1500 | H22: ok
E23: Sócio | F23: João | G23: =Software!K7+2000 -> 3000 | H23: ok
E24: Estágio | F24: Paulo | G24: ='Vendas e Engenharia'!N43 -> 1300 | H24: ok
E25: Sócio Adm | F25: Leon | G25: 900 | H25: ok
E26: mei | F26: Lorena | G26: 1000 | H26: ok
E27: mei | F27: Cleber | G27: ='Vendas e Engenharia'!N51 -> 3000 | H27: ok
E28: mei | F28: Igor A | G28: ='Vendas e Engenharia'!N47 -> 1500 | H28: ok
E29: mei | F29: Audrey | G29: ='Vendas e Engenharia'!N63 -> 5417 | H29: ok
E30: mei | F30: Tawany | G30: ='Vendas e Engenharia'!N59 -> 1300 | H30: ok
E31: Estágio | F31: Dantre | G31: 1000 | H31: ok
E32: Estágio | F32: Sandro | G32: 1000 | H32: ok
F33: Falta pagar | G33: =SUM(G12:G32) -> 72557.3
G37: 7163
G38: =SUM(G15,G19,G20,G27,G28,G14,G17,G12,G16) -> 39739.6
G39: =SUM(G37:G38) -> 46902.6
G40: 1621
G41: 1300

Sheet Projeções e Premissas
C3: Custo bruto folha | D3: atual | E3: Fev | F3: Julho | G3: Dez
C4: Jonildo | D4: 6100 | E4: 7500 | F4: 8000 | G4: 10000
C5: Gabriel | D5: 3000 | E5: 6000 | F5: =E5 -> 6000 | G5: 6000
C6: Igor | D6: 1700 | E6: 5000 | F6: =E6 -> 5000 | G6: 5000
C7: Fernando | D7: 4000 | E7: 4000 | F7: 6000 | G7: 14000
C8: Belo | D8: 3500 | E8: =D8 -> 3500 | F8: 5000 | G8: 10000
C9: Decézaris | D9: 4500 | E9: =D9 -> 4500 | F9: 6500 | G9: 10000
C10: Adryan | D10: 1500 | E10: 3200 | F10: 5500 | G10: 7500
C11: Macgyver | D11: 5100 | E11: =D11 -> 5100 | F11: =E11 -> 5100 | G11: 6000
C12: Diogo | D12: 2500 | E12: 2500 | F12: 3500 | G12: 4500
C13: Audrey | D13: 2500 | E13: 2500 | F13: 3500 | G13: 4500
C14: Est. Igor | D14: 1000 | E14: 1500 | F14: 1500 | G14: 2000
C15: Est. P. Araújo | D15: 1000 | E15: 1300 | F15: 1500 | G15: 2000
C16: Est. Tawanny | D16: 1000 | E16: 1000 | F16: 1000 | G16: 1500
C17: Leon | D17: 900 | E17: 4500 | F17: 4500 | G17: 4500
C18: RH | D18: 0 | E18: 1000 | F18: =E18 -> 1000 | G18: =F18 -> 1000
C19: Novo Vendedor | D19: 0 | G19: 5000
C20: Est. Cleber | D20: 1000 | E20: 2000 | F20: 3000 | G20: 5000
C21: João | D21: 1000 | E21: 2000 | F21: 2000 | G21: 2000
C22: Kalebe | D22: 1000 | E22: 1500 | F22: 2000 | G22: 3000
C23: Everaldo | D23: 1500 | E23: 1000 | F23: 1000 | G23: 1000
C24: Filipe | D24: 2500
C26: Total | D26: =SUM(D4:D25) -> 45300 | E26: =SUM(E4:E25) -> 59600 | F26: =SUM(F4:F25) -> 71600 | G26: =SUM(G4:G25) -> 104500
B30: Via de Pagamento | C30: Meio de Pagamento | D30: Membro | E30: Fixo | F30: Comissão Consultoria | G30: Comissão Obras
B31: Consultoria | C31: Sócio Adm | D31: Fernando | E31: 4000
B32: Consultoria | C32: Sócio | D32: Gabriel | E32: 6000 | F32: =2626.25 -> 2626.25
B33: Consultoria | C33: Sócio | D33: Jonildo | E33: 7500 | F33: 425 | G33: 510
B34: Consultoria | C34: Mei | D34: Igor | E34: 5000 | F34: =2875 -> 2875 | G34: =3010 -> 3010
B35: Consultoria | C35: Sócio Adm | D35: Belo | E35: 3500
B36: Consultoria/Obras | C36: Sócio | D36: Adryan | E36: =3200 -> 3200 | G36: 2397
B37: Consultoria | C37: Sócio | D37: Tiago | E37: 600
B38: Consultoria | C38: Mei | D38: Flavio | E38: 5100
B39: Consultoria | C39: Mei | D39: Diogo | E39: 2500
B40: Consultoria | C40: Sócio Adm | D40: Dec | E40: 4500
B41: Consultoria | C41: Mei | D41: Evera | E41: 1500
B42: Consultoria | C42: Sócio | D42: João | E42: 1000
B43: Consultoria | C43: Estágio | D43: Paulo | E43: 1300
B44: Consultoria | C44: Sócio Adm | D44: Leon | E44: 900
B45: Consultoria | C45: mei | D45: Kalebe
B46: Consultoria | C46: mei | D46: Cleber | E46: 3000
...

Sheet Vendas e Engenharia
F2: Time de Vendas | G2: Janeiro | H2: fevereiro | I2: março | J2: abril | K2: maio | L2: junho | M2: julho | N2: agosto | O2: setembro | P2: outubro | Q2: novembro | R2: dezembro
E3: Fernando | F3: Total | G3: =SUM(G4:G11) -> 4500 | H3: =SUM(H4:H11) -> 4000 | I3: =SUM(I4:I11) -> 4400 | J3: =SUM(J4:J11) -> 4000 | K3: =SUM(K4:K11) -> 4000 | L3: =SUM(L4:L11) -> 4000 | M3: =SUM(M4:M11) -> 5000 | N3: =SUM(N4:N11) -> 5000 | ... R3: =SUM(R4:R11) -> 0
F4: Medidores
F5: Vendas | G5: =500 -> 500 | I5: =400 -> 400
F6: P&D Plataforma
F7: Consultoria/P&D
F8: Diárias (Especialista)
F9: Diária (Ajudante)
F10: Plataforma | G10: 500
F11: Fixo | G11: 3500 | H11: 4000 | I11: 4000 | J11: 4000 | K11: 4000 | L11: 4000 | M11: 5000 | N11: 5000
F12: Deduções
E13: Gabriel | F13: Total | G13: =SUM(G14:G22) -> 5298.66 | H13: =SUM(H14:H22) -> 4894.23 | I13: =SUM(I14:I22) -> 8804.95 | J13: =SUM(J14:J22) -> 6626.45 | K13: =SUM(K14:K22) -> 11130.7 | L13: =SUM(L14:L22) -> 8698.7 | M13: =SUM(M14:M22) -> 8770.7 | N13: =SUM(N14:N22) -> 11300.7 | ... R13: =SUM(R14:R22) -> 0
F14: Comissão de Consultoria | G14: =283.33+266.66+198.34+190+150+198+207+150+627+183.33+225+100+150+90+200+252+198+130+300 -> 4098.66 | I14: =1895.75 -> 1895.75 | J14: =I14 -> 1895.75 | K14: =6400 -> 6400 | L14: =4968 -> 4968 | M14: =5040 -> 5040 | N14: =(9200+2700+20000+13000+10800+8000+6000+6000)*10% -> 7570
F15: Comissão de Obras | I15: =2178.5 -> 2178.5
F16: Venda de Lotes
F17: Gestão De Usina | G17: 1000
F18: Comissões 2025 | H18: 894.23 | I18: =730.7 -> 730.7 | J18: =I18 -> 730.7 | K18: =J18 -> 730.7 | L18: 730.7 | M18: 730.7 | N18: 730.7
F19: Diária (Ajudante)
F20: Instalações
F21: Fixo | G21: 2200 | H21: 6000 | I21: 6000 | J21: 6000 | K21: 6000 | L21: 5000 | M21: 5000 | N21: 5000
F22: Deduções | G22: -2000 | H22: -2000 | I22: -2000 | J22: -2000 | K22: -2000 | L22: -2000 | M22: -2000 | N22: -2000
E23: Jonildo | F23: Total | G23: =SUM(G24:G31) -> 7700 | H23: =SUM(H24:H31) -> 7500 | I23: =SUM(I24:I31) -> 11401.5 | J23: =SUM(J24:J31) -> 7500 | K23: =SUM(K24:K31) -> 7500 | L23: =SUM(L24:L31) -> 7500 | M23: =SUM(M24:M31) -> 7500 | N23: =SUM(N24:N31) -> 7500 | ... R23: =SUM(R24:R31) -> 0
F24: Consultoria
F25: Comissão de Pós-Venda | I25: =32500*5%+2276.5 -> 3901.5
F26: Gestão | G26: 2500
F27: Consultoria/P&D | G27: =500+200 -> 700
F28: Diárias (Especialista)
F29: Inspeções/Levantamentos
F30: Relatórios | G30: 4500
F31: Fixo | H31: 7500 | I31: 7500 | J31: 7500 | K31: 7500 | L31: 7500 | M31: 7500 | N31: 7500
F32: Deduções
E33: Igor | F33: Total | G33: =SUM(G34:G41) -> 5893 | H33: =SUM(H34:H41) -> 5865.5 | I33: =SUM(I34:I41) -> 7340.5 | J33: =SUM(J34:J41) -> 10885 | K33: =SUM(K34:K41) -> 9495 | L33: =SUM(L34:L42) -> 8745 | M33: =SUM(M34:M42) -> 10484 | N33: =SUM(N34:N42) -> 8868.6 | O33: =SUM(O34:O42) -> 0 | P33: =SUM(P34:P42) -> 0 | Q33: =SUM(Q34:Q42) -> 0 | R33: =SUM(R34:R42) -> 0
F34: Comissão de Consultoria | G34: =117+160+150+84+125+86+207+255+150+125+154+260+156+192+125+130+195+176+100+175+166+130+100+100 -> 3618 | I34: =500+135 -> 635 | J34: =1700+750+425 -> 2875 | K34: =1700+700+735+360+400+600 -> 4495 | L34: =1700+750+500+360+195+240 -> 3745 | M34: =1700+780+540+680+680+400+704 -> 5484 | N34: =1700+2168.6 -> 3868.6
F35: Venda de Lotes
F36: Comissões 2025 | H36: 678 | I36: 678
F37: Gestão De Usina | G37: 500
F38: Comissão Obras | G38: 575 | H38: 187.5 | I38: =187.5+840 -> 1027.5 | J38: =3010 -> 3010
F39: Diária (Ajudante)
F40: Gestão Financeira | G40: 200
F41: Fixo | G41: 1000 | H41: 5000 | I41: 5000 | J41: 5000 | K41: 5000 | L41: 5000 | M41: 5000 | N41: 5000
...

Sheet Hardware
E5: Time de Hardware | F5: Janeiro | G5: fevereiro | H5: março | I5: abril | J5: maio | K5: junho | L5: julho | M5: agosto | N5: setembro | O5: outubro | P5: novembro | Q5: dezembro
D6: Belo | E6: Total | F6: =SUM(F7:F15) -> 3500 | G6: =SUM(G7:G15) -> 3500 | H6: =SUM(H7:H15) -> 3500 | I6: =SUM(I7:I15) -> 3500 | J6: =SUM(J7:J15) -> 3500 | K6: =SUM(K7:K15) -> 3500 | L6: =SUM(L7:L15) -> 4500 | M6: =SUM(M7:M15) -> 4500 | ... Q6: =SUM(Q7:Q15) -> 0
E7: Medidores Instalados
E8: Manutenção
E9: Fabricação de medidores
E10: Diária Especialista
E11: Diária Ajudante
E12: Consultoria | F12: 1000 | G12: 1000 | H12: 1000 | I12: 1000 | J12: 1000 | K12: 1000 | L12: 2000 | M12: 4500
E13: Participação no Fat. Mensal
E14: Plataforma
E15: Desenvolvimento | F15: 2500 | G15: 2500 | H15: 2500 | I15: 2500 | J15: 2500 | K15: 2500 | L15: 2500
E16: Deduções
D17: Adryan | E17: Total | F17: =SUM(F18:F26) -> 3375 | G17: =SUM(G18:G26) -> 1500 | H17: =SUM(H18:H26) -> 1500 | I17: =SUM(I18:I26) -> 1621 | J17: =SUM(J18:J26) -> 1621 | K17: =SUM(K18:K27) -> 1621 | L17: =SUM(L18:L27) -> 1621 | M17: =SUM(M18:M27) -> 1621 | N17: =SUM(N18:N27) -> 0 | O17: =SUM(O18:O27) -> 0 | P17: =SUM(P18:P27) -> 0 | Q17: =SUM(Q18:Q27) -> 0
E18: Medidores Instalados
E19: Manutenção
E20: Fabricação de medidores
E21: Diária Especialista
E22: Diária Ajudante
E23: Participação no Fat. Vendas
E24: Inspeções/Levantamentos | F24: 1875
E25: Comissão de Vendas
E26: Desenvolvimento | F26: 1500 | G26: 1500 | H26: 1500 | I26: 1621 | J26: 1621 | K26: 1621 | L26: 1621 | M26: 1621
E27: Deduções
D28: Tiago | E28: Total | F28: =SUM(F29:F37) -> 600 | G28: =SUM(G29:G37) -> 600 | H28: =SUM(H29:H37) -> 600 | I28: =SUM(I29:I37) -> 600 | J28: =SUM(J29:J37) -> 600 | K28: =SUM(K29:K37) -> 600 | L28: =SUM(L29:L37) -> 600 | M28: =SUM(M29:M37) -> 600 | ... Q28: =SUM(Q29:Q37) -> 0
E29: Medidores Instalados
E30: Manutenção
E31: Fabricação de medidores
E32: Diária Especialista
E33: Diária Ajudante
E34: Participação no Fat. Vendas
E35: Participação no Fat. Mensal
E36: Repasse p/ recarga dos chips
E37: Desenvolvimento/Suporte | F37: 600 | G37: 600 | H37: 600 | I37: 600 | J37: 600 | K37: 600 | L37: 600 | M37: 600
E38: Deduções
D39: Macgyver | E39: Total | F39: =SUM(F40:F48) -> 5100 | G39: =SUM(G40:G48) -> 5100 | H39: =SUM(H40:H48) -> 5100 | I39: =SUM(I40:I48) -> 5100 | J39: =SUM(J40:J48) -> 5100 | K39: =SUM(K40:K49) -> 5100 | L39: =SUM(L40:L49) -> 5100 | M39: =SUM(M40:M49) -> 5100 | N39: =SUM(N40:N49) -> 0 | O39: =SUM(O40:O49) -> 0 | P39: =SUM(P40:P49) -> 0 | Q39: =SUM(Q40:Q49) -> 0
E40: Medidores Instalados
E41: Manutenção
E42: Fabricação de medidores
E43: Diária Especialista
E44: Diária Ajudante
...

Sheet Software
C3: Time de Software | D3: Janeiro | E3: fevereiro | F3: março | G3: abril | H3: maio | I3: junho | J3: julho | K3: agosto | L3: setembro | M3: outubro | N3: novembro | O3: dezembro
C4: Dec | D4: 4500 | E4: 4500 | F4: 4500 | G4: 4500 | H4: 4500 | I4: 4500 | J4: 4500 | K4: 4500
C6: Evera | D6: 1500 | E6: 1500 | F6: 1500 | G6: 1500 | H6: 1500 | I6: 1500 | J6: 1500 | K6: 1500
C7: João | D7: 998.4 | E7: 1000 | F7: 1000 | G7: 1000 | H7: 1000 | I7: 1000 | J7: 1000 | K7: 1000
C8: Kalebe | D8: 1000 | E8: 1000
C10: Total | D10: =SUM(D4:D8) -> 7998.4 | E10: =SUM(E4:E9) -> 8000 | F10: =SUM(F4:F9) -> 7000 | G10: =SUM(G4:G9) -> 7000 | H10: =SUM(H4:H9) -> 7000 | I10: =SUM(I4:I9) -> 7000 | J10: =SUM(J4:J9) -> 7000 | K10: =SUM(K4:K9) -> 7000 | L10: =SUM(L4:L9) -> 0 | ... O10: =SUM(O4:O9) -> 0
