Workbook

Sheet Resumão Geral
C3: Período | D3: Janeiro | E3: Fevereiro | F3: março | G3: abril | H3: maio | I3: junho | J3: julho | K3: agosto | L3: setembro | M3: outubro | N3: novembro | O3: dezembro
C5: Fontes de Receita (+) | D5: =SUM(D8,D14,D18,D22) -> 143250.9 | E5: =SUM(E8,E14,E18,E22) -> 143599.21 | F5: =SUM(F8,F14,F18,F22) -> 157197.52 | G5: =SUM(G8,G14,G18,G22) -> 170282.82 | H5: =SUM(H8,H14,H18,H22) -> 183685.6 | I5: =SUM(I8,I14,I18,I22) -> 223105.87 | J5: =SUM(J8,J14,J18,J22) -> 258553.33 | K5: =SUM(K8,K14,K18,K22) -> 286372 | ... O5: =SUM(O8,O14,O18,O22) -> 345814.67
C6: Quantidada de Projetos Fechados Consultoria | D6: ='Projeção Biel Ajustada'!E11 -> 8 | E6: ='Projeção Biel Ajustada'!F11 -> 9.6 | F6: ='Projeção Biel Ajustada'!G11 -> 12.8 | G6: ='Projeção Biel Ajustada'!H11 -> 14.08 | H6: ='Projeção Biel Ajustada'!I11 -> 15.36 | I6: ='Projeção Biel Ajustada'!J11 -> 16.64 | J6: ='Projeção Biel Ajustada'!K11 -> 17.92 | K6: ='Projeção Biel Ajustada'!L11 -> 19.2 | ... O6: ='Projeção Biel Ajustada'!P11 -> 19.2 | T6: Resultado Anual 2026 - Projetado | W6: Flags | Y6: Valor Por Cliente
C7: Quantidada de Projetos Fechados Obra | D7: ='Projeção Biel Ajustada'!E84 -> 1.04 | E7: ='Projeção Biel Ajustada'!F84 -> 1.248 | F7: ='Projeção Biel Ajustada'!G84 -> 1.664 | G7: ='Projeção Biel Ajustada'!H84 -> 1.8304 | H7: ='Projeção Biel Ajustada'!I84 -> 1.9968 | I7: ='Projeção Biel Ajustada'!J84 -> 2.1632 | J7: ='Projeção Biel Ajustada'!K84 -> 2.3296 | K7: ='Projeção Biel Ajustada'!L84 -> 2.496 | ... O7: ='Projeção Biel Ajustada'!P84 -> 2.496 | T7: Receitas | U7: =SUM(D5:O5) -> 2910186.4 | W7: Reserva de Caixa | X7: =SUM(D60:O60) -> 122037.72 | Y7: =X7/SUM($D$6:$O$7) -> 557.8408
C8: Receita Base | D8: =SUM(D9:D12) -> 122640.83 | E8: =SUM(E9:E12) -> 95669.14 | F8: =SUM(F9:F12) -> 72840.79 | G8: =SUM(G9:G12) -> 42055.15 | H8: =SUM(H9:H12) -> 28208.8 | I8: =SUM(I9:I12) -> 28208.8 | J8: =SUM(J9:J12) -> 28208.8 | K8: =SUM(K9:K12) -> 28208.8 | ... O8: =SUM(O9:O12) -> 28208.8 | T8: CSP | U8: =SUM(D27:O27) -> 469432.13 | W8: Reserva de Brindes Clientes | X8: =SUM(D59:O59) -> 65106.088 | Y8: =X8/SUM($D$6:$O$7) -> 297.60334
C9: Assinaturas | D9: =5300+1097.8+1230+80+1000 -> 8707.8 | E9: =5300+1097.8+1230+80 -> 7707.8 | F9: =5300+1097.8+1230+80 -> 7707.8 | G9: =5300+1097.8+1230+80 -> 7707.8 | H9: =5300+1097.8+1230+80 -> 7707.8 | I9: =5300+1097.8+1230+80 -> 7707.8 | J9: =5300+1097.8+1230+80 -> 7707.8 | K9: =5300+1097.8+1230+80 -> 7707.8 | L9: =5300+1097.8+1230+80 -> 7707.8 | ... O9: =5300+1097.8+1230+80 -> 7707.8 | T9: Lucro Bruto | U9: =U7-U8 -> 2440754.3 | W9: Reserva de Eventos | X9: =SUM(D58:O58) -> 32553.044 | Y9: =X9/SUM($D$6:$O$7) -> 148.80167
C10: Bra | D10: 20501 | E10: 20501 | F10: 20501 | G10: 20501 | H10: 20501 | I10: 20501 | J10: 20501 | K10: 20501 | L10: 20501 | M10: 20501 | N10: 20501 | O10: 20501 | T10: Margem Bruta | U10: =U9/U7 -> 0.83869345 | W10: Reserva de Brindes Membros | X10: =SUM(D57:O57) -> 10851.015 | Y10: =X10/SUM($D$6:$O$7) -> 49.600557
C11: Consultorias 2025 | D11: =59538.38+2250 -> 61788.38 | E11: =43916.69 -> 43916.69 | F11: 30263.33 | G11: 11173.35 | T11: Despesas | U11: =SUM(D45:O45) -> 1364604.9
C12: Obras 2025 | D12: =24893.65+6750 -> 31643.65 | E12: 23543.65 | F12: 14368.66 | G12: 2673 | T12: Lucro Operacional (Ebitda) | U12: =U9-U11 -> 1076149.4
T13: Margem Ebitda | U13: =U12/U7 -> 0.36978709 | W13: Meta de Contratos | X13: 1q | Y13: 2q | Z13: 3q | AA13: 4q | AB13: Total
C14: Consultoria | D14: =D15 -> 15843.4 | E14: =E15 -> 37443.4 | F14: =F15 -> 66243.4 | G14: =G15 -> 101443.4 | H14: =H15 -> 124000 | I14: =I15 -> 148160 | J14: =J15 -> 168640 | K14: =K15 -> 191040 | ... O14: =O15 -> 240000 | T14: Despesas Financeiras | U14: =SUM(D40:O43) -> 98420.222 | W14: Consultorias | X14: =SUM('Projeção Biel Ajustada'!E13:G13) -> 264973.6 | Y14: =SUM('Projeção Biel Ajustada'!H13:J13) -> 477440 | Z14: =SUM('Projeção Biel Ajustada'!K13:M13) -> 673280 | AA14: =SUM('Projeção Biel Ajustada'!N13:P13) -> 714240 | AB14: =SUM(X14:AA14) -> 2129933.6
C15: Vendas de Consultora | D15: ='Projeção Biel Ajustada'!E18 -> 15843.4 | E15: ='Projeção Biel Ajustada'!F18 -> 37443.4 | F15: ='Projeção Biel Ajustada'!G18 -> 66243.4 | G15: ='Projeção Biel Ajustada'!H18 -> 101443.4 | H15: ='Projeção Biel Ajustada'!I18 -> 124000 | I15: ='Projeção Biel Ajustada'!J18 -> 148160 | J15: ='Projeção Biel Ajustada'!K18 -> 168640 | K15: ='Projeção Biel Ajustada'!L18 -> 191040 | ... O15: ='Projeção Biel Ajustada'!P18 -> 240000 | T15: Impostos | U15: =SUM(D39:O39) -> 397296.53 | W15: Obras | X15: =SUM('Projeção Biel Ajustada'!E85:G85) -> 72453.333 | Y15: =SUM('Projeção Biel Ajustada'!H85:J85) -> 109824 | Z15: =SUM('Projeção Biel Ajustada'!K85:M85) -> 137280 | AA15: =SUM('Projeção Biel Ajustada'!N85:P85) -> 141856 | AB15: =SUM(X15:AA15) -> 461413.33
T16: Lucro Líquido | U16: =U12-SUM(U14:U15) -> 580432.63 | W16: Plataforma | Y16: =SUM(G23:I23) -> 1792 | Z16: =SUM(J23:L23) -> 5017.6 | AA16: =SUM(M23:O23) -> 8640 | AB16: =SUM(X16:AA16) -> 15449.6
T17: Margem Líquida | U17: =U16/U7 -> 0.19944861 | W17: Plataforma Ger. Carr | Y17: =SUM(I24) -> 332.8 | Z17: =SUM(J24:L24) -> 3251.2 | AA17: =SUM(M24:O24) -> 6873.6 | AB17: =SUM(X17:AA17) -> 10457.6
C18: Obras | D18: =D19 -> 4766.6667 | E18: =E19 -> 10486.667 | F18: =F19 -> 18113.333 | G18: =G19 -> 26502.667 | H18: =H19 -> 30888 | I18: =I19 -> 35082.667 | J18: =J19 -> 38133.333 | K18: =K19 -> 41184 | ... O18: =O19 -> 47666.667 | W18: Setup | Y18: ='Projeção Biel Ajustada'!J70 -> 20800 | Z18: =SUM('Projeção Biel Ajustada'!K70:M70) -> 72000 | AA18: =SUM('Projeção Biel Ajustada'!N70:P70) -> 74400 | AB18: =SUM(X18:AA18) -> 167200
C19: Vendas de Obras | D19: ='Projeção Biel Ajustada'!E90 -> 4766.6667 | E19: ='Projeção Biel Ajustada'!F90 -> 10486.667 | F19: ='Projeção Biel Ajustada'!G90 -> 18113.333 | G19: ='Projeção Biel Ajustada'!H90 -> 26502.667 | H19: ='Projeção Biel Ajustada'!I90 -> 30888 | I19: ='Projeção Biel Ajustada'!J90 -> 35082.667 | J19: ='Projeção Biel Ajustada'!K90 -> 38133.333 | K19: ='Projeção Biel Ajustada'!L90 -> 41184 | ... O19: ='Projeção Biel Ajustada'!P90 -> 47666.667 | W19: Total | X19: =SUM(X14:X18) -> 337426.93 | Y19: =SUM(Y14:Y18) -> 610188.8 | Z19: =SUM(Z14:Z18) -> 890828.8 | AA19: =SUM(AA14:AA18) -> 946009.6 | AB19: =SUM(AB14:AB18) -> 2784454.1
C22: Plataforma | D22: =SUM(D23:D25) -> 0 | E22: =SUM(E23:E25) -> 0 | F22: =SUM(F23:F25) -> 0 | G22: =SUM(G23:G25) -> 281.6 | H22: =SUM(H23:H25) -> 588.8 | I22: =SUM(I23:I25) -> 11654.4 | J22: =SUM(J23:J25) -> 23571.2 | K22: =SUM(K23:K25) -> 25939.2 | ... O22: =SUM(O23:O25) -> 29939.2
C23: MRR Plataforma | G23: ='Projeção Biel Ajustada'!H60 -> 281.6 | H23: ='Projeção Biel Ajustada'!I60 -> 588.8 | I23: ='Projeção Biel Ajustada'!J60 -> 921.6 | J23: ='Projeção Biel Ajustada'!K60 -> 1280 | K23: ='Projeção Biel Ajustada'!L60 -> 1664 | L23: ='Projeção Biel Ajustada'!M60 -> 2073.6 | M23: ='Projeção Biel Ajustada'!N60 -> 2496 | N23: ='Projeção Biel Ajustada'!O60 -> 2880 | O23: ='Projeção Biel Ajustada'!P60 -> 3264
C24: MRR Plataforma de Geren. de Carr | I24: ='Projeção Biel Ajustada'!J68 -> 332.8 | J24: ='Projeção Biel Ajustada'!K68 -> 691.2 | K24: ='Projeção Biel Ajustada'!L68 -> 1075.2 | L24: ='Projeção Biel Ajustada'!M68 -> 1484.8 | M24: ='Projeção Biel Ajustada'!N68 -> 1907.2 | N24: ='Projeção Biel Ajustada'!O68 -> 2291.2 | O24: ='Projeção Biel Ajustada'!P68 -> 2675.2
C25: Setup | I25: ='Projeção Biel Ajustada'!J73 -> 10400 | J25: ='Projeção Biel Ajustada'!K73 -> 21600 | K25: ='Projeção Biel Ajustada'!L73 -> 23200 | L25: ='Projeção Biel Ajustada'!M73 -> 24800 | M25: ='Projeção Biel Ajustada'!N73 -> 26000 | N25: ='Projeção Biel Ajustada'!O73 -> 25200 | O25: ='Projeção Biel Ajustada'!P73 -> 24000
C27: Custos Operação (-) | D27: =SUM(D28:D33) -> 22949.737 | E27: =SUM(E28:E33) -> 24412.73 | F27: =SUM(F28:F33) -> 31955.065 | G27: =SUM(G28:G33) -> 32978.067 | H27: =SUM(H28:H33) -> 35165.6 | I27: =SUM(I28:I33) -> 39759.733 | J27: =SUM(J28:J33) -> 42625.867 | K27: =SUM(K28:K33) -> 46452 | ... O27: =SUM(O28:O33) -> 46452
C28: Comissão de Vendas | D28: ='Projeção Biel Ajustada'!E112 -> 2061.0067 | E28: ='Projeção Biel Ajustada'!F112 -> 2732 | F28: ='Projeção Biel Ajustada'!G112 -> 7285.3333 | G28: ='Projeção Biel Ajustada'!H112 -> 8717.8667 | H28: ='Projeção Biel Ajustada'!I112 -> 9510.4 | I28: ='Projeção Biel Ajustada'!J112 -> 12174.933 | J28: ='Projeção Biel Ajustada'!K112 -> 13111.467 | K28: ='Projeção Biel Ajustada'!L112 -> 15008 | ... O28: ='Projeção Biel Ajustada'!P112 -> 15008
C29: Materiais de Obras | D29: ='Projeção Biel Ajustada'!E91+(D12*20%) -> 14908.73 | E29: ='Projeção Biel Ajustada'!F91+(E12*20%) -> 15004.73 | F29: ='Projeção Biel Ajustada'!G91+(F12*20%) -> 16601.732 | G29: ='Projeção Biel Ajustada'!H91+(G12*20%) -> 15635.4 | H29: ='Projeção Biel Ajustada'!I91 -> 16473.6 | I29: ='Projeção Biel Ajustada'!J91 -> 17846.4 | J29: ='Projeção Biel Ajustada'!K91 -> 19219.2 | K29: ='Projeção Biel Ajustada'!L91 -> 20592 | L29: ='Projeção Biel Ajustada'!M91 -> 21964.8 | M29: ='Projeção Biel Ajustada'!N91 -> 22651.2 | N29: ='Projeção Biel Ajustada'!O91 -> 20592 | O29: ='Projeção Biel Ajustada'!P91 -> 20592
C30: Custos de Execução de Obras (Transporte e alimentação) | D30: ='Premissas gerais'!$B$126+'Premissas gerais'!$B$125 -> 2500 | E30: ='Premissas gerais'!$B$126+'Premissas gerais'!$B$125 -> 2500 | F30: ='Premissas gerais'!$B$126+'Premissas gerais'!$B$125 -> 2500 | G30: ='Premissas gerais'!$B$126+'Premissas gerais'!$B$125 -> 2500 | H30: ='Premissas gerais'!$B$126+'Premissas gerais'!$B$125 -> 2500 | I30: ='Premissas gerais'!$B$126+'Premissas gerais'!$B$125 -> 2500 | J30: ='Premissas gerais'!$B$126+'Premissas gerais'!$B$125 -> 2500 | K30: ='Premissas gerais'!$B$126+'Premissas gerais'!$B$125 -> 2500 | ... O30: ='Premissas gerais'!$B$126+'Premissas gerais'!$B$125 -> 2500
C31: Custo do Serviço Prestado Consult. | D31: ='Projeção Biel Ajustada'!E36 -> 3480 | E31: ='Projeção Biel Ajustada'!F36 -> 4176 | F31: ='Projeção Biel Ajustada'!G36 -> 5568 | G31: ='Projeção Biel Ajustada'!H36 -> 6124.8 | H31: ='Projeção Biel Ajustada'!I36 -> 6681.6 | I31: ='Projeção Biel Ajustada'!J36 -> 7238.4 | J31: ='Projeção Biel Ajustada'!K36 -> 7795.2 | K31: ='Projeção Biel Ajustada'!L36 -> 8352 | ... O31: ='Projeção Biel Ajustada'!P36 -> 8352
C32: Materiais de Consultoria
C34: Lucro Bruto | D34: =D5-D27 -> 120301.16 | E34: =E5-E27 -> 119186.48 | F34: =F5-F27 -> 125242.46 | G34: =G5-G27 -> 137304.75 | H34: =H5-H27 -> 148520 | I34: =I5-I27 -> 183346.13 | J34: =J5-J27 -> 215927.47 | K34: =K5-K27 -> 239920 | ... O34: =O5-O27 -> 299362.67
C35: Margem Bruta | D35: =D34/D5 -> 0.83979342 | E35: =E34/E5 -> 0.82999398 | F35: =F34/F5 -> 0.7967203 | G35: =G34/G5 -> 0.80633356 | H35: =H34/H5 -> 0.80855549 | I35: =I34/I5 -> 0.82178983 | J35: =J34/J5 -> 0.83513704 | K35: =K34/K5 -> 0.8377914 | ... O35: =O34/O5 -> 0.86567371
C37: Despesas Financeiras (-) | D37: =SUM(D39,D40,D41,D42,D43) -> 28964.88 | E37: =SUM(E39,E40,E41,E42,E43) -> 25993.252 | F37: =SUM(F39,F40,F41,F42,F43) -> 26403.297 | G37: =SUM(G39,G40,G41,G42,G43) -> 28625.376 | H37: =SUM(H39,H40,H41,H42,H43) -> 30811.531 | I37: =SUM(I39,I40,I41,I42,I43) -> 33082.136 | J37: =SUM(J39,J40,J41,J42,J43) -> 39040.924 | K37: =SUM(K39,K40,K41,K42,K43) -> 47275.175 | ... O37: =SUM(O39,O40,O41,O42,O43) -> 65331.508
C38: Alíquota Simples Nacional | D38: ='Premissas gerais'!N115 -> 0.12798836 | E38: ='Premissas gerais'!O115 -> 0.13016164 | F38: ='Premissas gerais'!P115 -> 0.13190586 | G38: ='Premissas gerais'!Q115 -> 0.13388971 | H38: ='Premissas gerais'!R115 -> 0.13574142 | I38: ='Premissas gerais'!S115 -> 0.13753829 | J38: ='Premissas gerais'!T115 -> 0.13939093 | K38: ='Premissas gerais'!U116 -> 0.14313122 | L38: ='Premissas gerais'!V116 -> 0.14905564 | M38: ='Premissas gerais'!W116 -> 0.15478651 | N38: ='Premissas gerais'!X116 -> 0.15948359 | O38: ='Premissas gerais'!Y116 -> 0.16385178
C39: Impostos sobre o Faturamento | D39: ='Premissas gerais'!M114*D38 -> 20242.64 | E39: =D5*E38 -> 18645.772 | F39: =E5*F38 -> 18941.577 | G39: =F5*G38 -> 21047.131 | H39: =G5*H38 -> 23114.431 | I39: =H5*I38 -> 25263.803 | J39: =I5*J38 -> 31098.935 | K39: =J5*K38 -> 37007.055 | L39: =K5*L38 -> 42685.361 | ... O39: =N5*O38 -> 56733.132
C40: INSS | D40: =11%*1621*4 -> 713.24 | E40: =11%*1621*8 -> 1426.48 | F40: =11%*1621*8 -> 1426.48 | G40: =11%*1621*8 -> 1426.48 | H40: =11%*1621*8 -> 1426.48 | I40: =11%*1621*8 -> 1426.48 | J40: =11%*1621*8 -> 1426.48 | K40: =11%*1621*8 -> 1426.48 | L40: =11%*1621*8 -> 1426.48 | ... O40: =11%*1621*8 -> 1426.48
C41: CIM | D41: 2200 | K41: 2200
C42: Pagamento do Empréstimo Caixa | D42: 5600 | E42: =D42*1.02 -> 5712 | F42: =E42*1.02 -> 5826.24 | G42: =F42*1.02 -> 5942.7648 | H42: =G42*1.02 -> 6061.6201 | I42: =H42*1.02 -> 6182.8525 | J42: =I42*1.02 -> 6306.5095 | K42: =J42*1.02 -> 6432.6397 | L42: =K42*1.02 -> 6561.2925 | ... O42: =N42*1.02 -> 6962.8961
C43: Tarifas Bancárias | D43: =69+70+70 -> 209 | E43: =69+70+70 -> 209 | F43: =69+70+70 -> 209 | G43: =69+70+70 -> 209 | H43: =69+70+70 -> 209 | I43: =69+70+70 -> 209 | J43: =69+70+70 -> 209 | K43: =69+70+70 -> 209 | ... O43: =69+70+70 -> 209
C45: Custos Fixos (-) | D45: =SUM(D47,D50,D54) -> 87355.07 | E45: =SUM(E47,E50,E54) -> 91948.019 | F45: =SUM(F47,F50,F54) -> 94486.535 | G45: =SUM(G47,G50,G54) -> 97511.329 | H45: =SUM(H47,H50,H54) -> 99664.576 | I45: =SUM(I47,I50,I54) -> 103329.18 | J45: =SUM(J47,J50,J54) -> 120600.61 | K45: =SUM(K47,K50,K54) -> 123462.32 | ... O45: =SUM(O47,O50,O54) -> 161201.01
C47: Escritório, Jurídico, Contábil e Outros | D47: =SUM(D48:D49) -> 9721 | E47: =SUM(E48:E49) -> 9721 | F47: =SUM(F48:F49) -> 9721 | G47: =SUM(G48:G49) -> 9721 | H47: =SUM(H48:H49) -> 9721 | I47: =SUM(I48:I49) -> 9721 | J47: =SUM(J48:J49) -> 9721 | K47: =SUM(K48:K49) -> 9721 | ... O47: =SUM(O48:O49) -> 9721
C48: Escritório (água, luz, internet, energia, infra. e copa) | D48: ='Premissas gerais'!$B$90 -> 7000 | E48: ='Premissas gerais'!$B$90 -> 7000 | F48: ='Premissas gerais'!$B$90 -> 7000 | G48: ='Premissas gerais'!$B$90 -> 7000 | H48: ='Premissas gerais'!$B$90 -> 7000 | I48: ='Premissas gerais'!$B$90 -> 7000 | J48: ='Premissas gerais'!$B$90 -> 7000 | K48: ='Premissas gerais'!$B$90 -> 7000 | ... O48: ='Premissas gerais'!$B$90 -> 7000
C49: Jurídico e Contábil | D49: ='Premissas gerais'!$B$94 -> 2721 | E49: ='Premissas gerais'!$B$94 -> 2721 | F49: ='Premissas gerais'!$B$94 -> 2721 | G49: ='Premissas gerais'!$B$94 -> 2721 | H49: ='Premissas gerais'!$B$94 -> 2721 | I49: ='Premissas gerais'!$B$94 -> 2721 | J49: ='Premissas gerais'!$B$94 -> 2721 | K49: ='Premissas gerais'!$B$94 -> 2721 | ... O49: ='Premissas gerais'!$B$94 -> 2721
C50: Custos Fixos Time + Marketing | D50: =SUM(D51:D53) -> 60960 | E50: =SUM(E51:E53) -> 59600 | F50: =SUM(F51:F53) -> 59600 | G50: =SUM(G51:G53) -> 59600 | H50: =SUM(H51:H53) -> 59600 | I50: =SUM(I51:I53) -> 59600 | J50: =SUM(J51:J53) -> 73600 | K50: =SUM(K51:K53) -> 73600 | ... O50: =SUM(O51:O53) -> 105000
...

Sheet Premissas gerais
A1: Funil de Vendas | B1: Numero | C1: /Dias | D1: Indicadores | E1: Taxa | F1: Custo Unitário | N1: Curvas Base / Meses | O1: 1 | P1: 2 | Q1: 3 | R1: 4 | S1: 5 | T1: 6 | U1: 7 | V1: 8 | W1: 9 | X1: 10 | Y1: 11 | Z1: 12 | AA1: Total
A2: Contato | B2: 1200 | C2: =B2/($B$8*30) -> 3.3333333 | F2: =$B$11/B2 -> 640.3375 | L2: Histórico 2025 | M2: Qtd. Vendedores | N2: =AVERAGE(O2:Z2) -> 70166.667 | O2: 18000 | P2: 38000 | Q2: 11000 | R2: 76000 | S2: 64000 | T2: 77000 | U2: 70000 | V2: 105000 | W2: 82000 | X2: 112000 | Y2: 99000 | Z2: 90000 | AA2: =SUM(O2:Z2) -> 842000
A3: Lead | B3: 587 | C3: =B3/($B$8*30) -> 1.6305556 | D3: Lead/Contato | E3: =B3/B2 -> 0.48916667 | F3: =$B$11/B3 -> 1309.0375 | K3: Faturamento Anual | L3: Ref. 2º Sem 2025 | M3: - | N3: =AVERAGE(U2:Z2)*0.9 -> 83700 | O3: =O2/$N$2 -> 0.25653207 | P3: =P2/$N$2 -> 0.5415677 | Q3: =Q2/$N$2 -> 0.1567696 | R3: =R2/$N$2 -> 1.0831354 | S3: =S2/$N$2 -> 0.91211401 | T3: =T2/$N$2 -> 1.0973872 | U3: =U2/$N$2 -> 0.9976247 | V3: =V2/$N$2 -> 1.4964371 | ... Z3: =Z2/$N$2 -> 1.2826603 | AB3: XPEG
A4: Visita | B4: 301 | C4: =B4/($B$8*30) -> 0.83611111 | D4: Visita/Lead | E4: =B4/B3 -> 0.51277683 | F4: =$B$11/B4 -> 2552.8405 | K4: =N4*12 -> 1004400 | L4: Vendedor | M4: 1 | N4: =AVERAGE(O4:Z4) -> 83700 | O4: =O$3*$N$3*$M4 -> 21471.734 | P4: =P$3*$N$3*$M4 -> 45329.216 | Q4: =Q$3*$N$3*$M4 -> 13121.615 | R4: =R$3*$N$3*$M4 -> 90658.432 | S4: =S$3*$N$3*$M4 -> 76343.943 | T4: =T$3*$N$3*$M4 -> 91851.306 | U4: =U$3*$N$3*$M4 -> 83501.188 | V4: =V$3*$N$3*$M4 -> 125251.78 | ... Z4: =Z$3*$N$3*$M4 -> 107358.67 | AA4: =SUM(O4:Z4) -> 1004400
A5: Apresentações/Proposts | B5: 290 | C5: =B5/($B$8*30) -> 0.80555556 | D5: Apresentação/Visita | E5: =B5/B4 -> 0.96345515 | F5: =$B$11/B5 -> 2649.6724 | K5: =N5*12 -> 2008800 | L5: Vendedor | M5: 2 | N5: =M5*N3 -> 167400 | O5: =O$3*$N$3*$M5 -> 42943.468 | P5: =P$3*$N$3*$M5 -> 90658.432 | Q5: =Q$3*$N$3*$M5 -> 26243.23 | R5: =R$3*$N$3*$M5 -> 181316.86 | S5: =S$3*$N$3*$M5 -> 152687.89 | T5: =T$3*$N$3*$M5 -> 183702.61 | U5: =U$3*$N$3*$M5 -> 167002.38 | V5: =V$3*$N$3*$M5 -> 250503.56 | ... Z5: =Z$3*$N$3*$M5 -> 214717.34 | AA5: =SUM(O5:Z5) -> 2008800
A6: Fechamento | B6: =103-6 -> 97 | C6: =B6/($B$8*30) -> 0.26944444 | D6: Fechamento/Apresentação | E6: =B6/B5 -> 0.33448276 | F6: =$B$11/B6 -> 7921.701 | K6: =N6*12 -> 2511000 | L6: Vendedor | M6: 2.5 | N6: =M6*N4 -> 209250 | O6: =O$3*$N$3*$M6 -> 53679.335 | P6: =P$3*$N$3*$M6 -> 113323.04 | Q6: =Q$3*$N$3*$M6 -> 32804.038 | R6: =R$3*$N$3*$M6 -> 226646.08 | S6: =S$3*$N$3*$M6 -> 190859.86 | T6: =T$3*$N$3*$M6 -> 229628.27 | U6: =U$3*$N$3*$M6 -> 208752.97 | V6: =V$3*$N$3*$M6 -> 313129.45 | ... Z6: =Z$3*$N$3*$M6 -> 268396.67 | AA6: =SUM(O6:Z6) -> 2511000
A7: Pós-venda | B7: 21 | C7: =B7/($B$8*30) -> 0.058333333 | D7: Pós-venda/Fechamento | E7: =B7/B6 -> 0.21649485 | F7: =$B$11/B7 -> 36590.714 | K7: =N7*12 -> 3013200 | L7: Vendedor | M7: 3 | N7: =M7*N3 -> 251100 | O7: =O$3*$N$3*$M7 -> 64415.202 | P7: =P$3*$N$3*$M7 -> 135987.65 | Q7: =Q$3*$N$3*$M7 -> 39364.846 | R7: =R$3*$N$3*$M7 -> 271975.3 | S7: =S$3*$N$3*$M7 -> 229031.83 | T7: =T$3*$N$3*$M7 -> 275553.92 | U7: =U$3*$N$3*$M7 -> 250503.56 | V7: =V$3*$N$3*$M7 -> 375755.34 | ... Z7: =Z$3*$N$3*$M7 -> 322076.01 | AA7: =SUM(O7:Z7) -> 3013200
A8: Período de Análise (meses) | B8: 12 | F8: =$B$11/B8 -> 64033.75 | K8: =N8*12 -> 4017600 | L8: Vendedor | M8: 4 | N8: =M8*N3 -> 334800 | O8: =O$3*$N$3*$M8 -> 85886.936 | P8: =P$3*$N$3*$M8 -> 181316.86 | Q8: =Q$3*$N$3*$M8 -> 52486.461 | R8: =R$3*$N$3*$M8 -> 362633.73 | S8: =S$3*$N$3*$M8 -> 305375.77 | T8: =T$3*$N$3*$M8 -> 367405.23 | U8: =U$3*$N$3*$M8 -> 334004.75 | V8: =V$3*$N$3*$M8 -> 501007.13 | ... Z8: =Z$3*$N$3*$M8 -> 429434.68 | AA8: =SUM(O8:Z8) -> 4017600
A9: Fechamento Mensal | B9: =B6/B8 -> 8.0833333 | F9: =$B$11/B9 -> 95060.412
A10: Total Orçado | B10: =2533162.95-130000 -> 2403163 | C10: =B10/($B$8*(365/12)) -> 6584.0081 | F10: =E11*B10 -> 768405
A11: Total Fechado | B11: 768405 | C11: =B11/($B$8*365/12) -> 2105.2192 | D11: Fechado/Orçado (R$) | E11: =B11/B10 -> 0.31974736 | L11: =N7/8000 -> 31.3875
A12: Qtd Total de Orçamentos | B12: 301 | C12: =B12/($B$8*365/12) -> 0.82465753 | L12: =L11*3 -> 94.1625
A13: Qtd Total de Fechamentos | B13: =B6 -> 97 | C13: =B13/($B$8*365/12) -> 0.26575342 | D13: Fechado/Orçado (Qtd) | E13: =B13/B12 -> 0.32225914 | L13: =L12*2 -> 188.325 | N13: Histórico de Orçamentos | O13: 86000 | P13: 103000 | Q13: 82000 | R13: 200000 | S13: 153000 | T13: 143000 | U13: 268000 | V13: 335000 | W13: 295000 | X13: 232000 | Y13: 203000 | Z13: 200000 | AA13: =SUM(O13:Z13) -> 2300000
A15: Indicadores por Vendedor por Mês | C15: Indicadores Originais 2025 | D15: Taxa (%) | E15: Valor Simulado | G15: Projeção Simplificada | H15: Mês | I15: Ano | L15: 5000 | N15: antes | O15: 18000 | P15: 38000 | Q15: 11000 | R15: 76000 | S15: 64000 | T15: 77000 | U15: 70000 | V15: 105000 | W15: 82000 | X15: 112000 | Y15: 99000 | Z15: 90000 | AA15: =SUM(O15:Z15) -> 842000
A16: Qtd. de Vendedores | B16: 2 | C16: 1 | D16: 1 | E16: Qtd de Vendedores | F16: =D16*B16 -> 2 | G16: Qtd. Vendedores | H16: 2 | L16: =L13/L15 -> 0.037665 | N16: dinheiro em caixa | O16: 20000 | P16: 23000 | Q16: 10000 | R16: 20000 | S16: 38000 | T16: 34000 | U16: 53000 | V16: 71000 | W16: 66000 | X16: 83000 | Y16: 83000 | Z16: 75000
A17: Qtd. Contatos | B17: =B2/($B$8*$B$16) -> 50 | C17: 1 | D17: 3.2 | E17: Qtd de Contatos | F17: =D17*B17 -> 160 | G17: Contatos | H17: =F17*$H$16 -> 320 | I17: =H17*12 -> 3840
A18: Qtd. Lead | B18: =B3/($B$8*$B$16) -> 24.458333 | C18: 0.48916667 | D18: =E3 -> 0.48916667 | E18: Lead/Contato | F18: =F17*D18 -> 78.266667 | G18: Lead | H18: =F18*$H$16 -> 156.53333 | I18: =H18*12 -> 1878.4
A19: Qtd. Visita | B19: =B4/($B$8*$B$16) -> 12.541667 | C19: 0.51277683 | D19: =E4 -> 0.51277683 | E19: Visita/Lead | F19: =F18*D19 -> 40.133333 | G19: Visita | H19: =F19*$H$16 -> 80.266667 | I19: =H19*12 -> 963.2
A20: Qtd. Apresentações | B20: =B5/($B$8*$B$16) -> 12.083333 | C20: 0.96345515 | D20: =E5 -> 0.96345515 | E20: Apresentação/Visita | F20: =F19*D20 -> 38.666667 | G20: Apresentações | H20: =F20*$H$16 -> 77.333333 | I20: =H20*12 -> 928
A21: Qtd. Fechamento | B21: =B6/($B$8*$B$16) -> 4.0416667 | C21: 0.33448276 | D21: =E6 -> 0.33448276 | E21: Fechamento/Apresentação | F21: =F20*D21 -> 12.933333 | G21: Fechamento | H21: =F21*$H$16 -> 25.866667 | I21: =H21*12 -> 310.4
A22: Qtd. Pós-venda | B22: =B7/($B$8*$B$16) -> 0.875 | C22: 0.21649485 | D22: =E7 -> 0.21649485 | E22: Pós-venda/Fechamento | F22: =F21*D22 -> 2.8 | G22: Pós-venda | H22: =F22*$H$16 -> 5.6 | I22: =H22*12 -> 67.2
A23: Total Orçado | B23: =B10/($B$8*$B$16) -> 100131.79 | C23: 1 | D23: =B12/$B$4 -> 1 | E23: Orçamentos/Visita | F23: =D23*B25 -> 12.541667 | G23: Faturamento | H23: =F27*F26*H16 -> 196035.69 | I23: =H23*12 -> 2352428.3
A24: Total Fechado | B24: =B11/($B$8*$B$16) -> 32016.875 | C24: 0.32225914 | D24: =B13/$B$4 -> 0.32225914 | E24: Fechamento/Orçamento | F24: =D24*F23 -> 4.0416667
A25: Qtd. Orçamentos | B25: =B12/($B$8*$B$16) -> 12.541667 | C25: 1 | D25: 1 | E25: Orçamentos/mês | F25: =F20 -> 38.666667
A26: Qtd. Fechamentos | B26: =B13/($B$8*$B$16) -> 4.0416667 | C26: =E13 -> 0.32225914 | D26: 0.32 | E26: Fechamentos/mês | F26: =D26*F25 -> 12.373333
A27: Ticket Médio | B27: =B24/B26 -> 7921.701 | C27: 1 | D27: 1 | E27: Novo Ticket Médio | F27: =D27*B27 -> 7921.701
E28: Faturamento Mensal/Vendedor | F28: =F27*F26 -> 98017.847
A30: Margem Lucro Operacional | B30: R$ | C30: %
A31: Ticket Médio | B31: =F27 -> 7921.701 | C31: 1
A32: Imposto | B32: =C32*B31 -> 1267.4722 | C32: 0.16
A33: Custo Operacional | B33: =B31*C33 -> 3168.6804 | C33: 0.4
A34: Custo de Vendas | B34: =C34*B31 -> 792.1701 | C34: 0.1
A35: Orçamento Mkt + CS + Relac. | B35: =C35*B31 -> 396.08505 | C35: 0.05
A36: Margem Bruta | B36: =B31-B32-B33-B34-B35 -> 2297.2933 | C36: =B36/B31 -> 0.29
A37: Prática 1/4 cai no mês | B37: =B36/4 -> 574.32332
A40: Custo Fixo | B40: =SUM(B41:B48) -> 15000 | C40: Total
A41: Aluguel + Dívida | B41: 10000 | E41: =10*30*12 -> 3600
A42: Outros custos | B42: 5000 | E42: =11*0.5*1500 -> 8250
A43: - | B43: =B41*C43 -> 0 | E43: 3000
A44: - | B44: =B42*C44 -> 0
...

Sheet Projeção Biel Ajustada
A1: Faturamento Consultoria
A2: Mês | B2: Total | C2: Média | D2: Referência | E2: 1 | F2: 2 | G2: 3 | H2: 4 | I2: 5 | J2: 6 | K2: 7 | L2: 8 | M2: 9 | N2: 10 | O2: 11 | P2: 12
A3: Curva Faturamento R$ | B3: =SUM(E3:P3) -> 2008800 | C3: =AVERAGE(E3:P3) -> 167400 | E3: ='Premissas gerais'!O5 -> 42943.468 | F3: ='Premissas gerais'!P5 -> 90658.432 | G3: ='Premissas gerais'!Q5 -> 26243.23 | H3: ='Premissas gerais'!R5 -> 181316.86 | I3: ='Premissas gerais'!S5 -> 152687.89 | J3: ='Premissas gerais'!T5 -> 183702.61 | K3: ='Premissas gerais'!U5 -> 167002.38 | L3: ='Premissas gerais'!V5 -> 250503.56 | ... P3: ='Premissas gerais'!Z5 -> 214717.34
A4: Curva Faturamento % | B4: 1 | C4: =AVERAGE(E4:P4) -> 1 | E4: =E3/$C$3 -> 0.25653207 | F4: =F3/$C$3 -> 0.5415677 | G4: =G3/$C$3 -> 0.1567696 | H4: =H3/$C$3 -> 1.0831354 | I4: =I3/$C$3 -> 0.91211401 | J4: =J3/$C$3 -> 1.0973872 | K4: =K3/$C$3 -> 0.9976247 | L4: =L3/$C$3 -> 1.4964371 | ... P4: =P3/$C$3 -> 1.2826603 | V4: c1 | W4: c2 | X4: c3 | Y4: c4 | AA4: c1 | AB4: c2 | AC4: c3 | AD4: c4
A5: Qtd Vendedores | B5: =C5 -> 2 | C5: =AVERAGE(E5:P5) -> 2 | D5: 2 | E5: =D5 -> 2 | F5: =E5 -> 2 | G5: =F5 -> 2 | H5: =G5 -> 2 | I5: =H5 -> 2 | J5: =I5 -> 2 | K5: 2 | L5: =K5 -> 2 | M5: =L5 -> 2 | N5: =M5 -> 2 | O5: =N5 -> 2 | P5: =O5 -> 2 | U5: Ticket médio | V5: 10000 | W5: 10000 | X5: 10000 | Y5: 10000 | Z5: Ticket médio | AA5: 10000 | AB5: 10000 | AC5: 10000 | AD5: 10000
A6: Funil de Vendas Atual | B6: 84 | E6: 84 | U6: Comissão % | V6: 0 | W6: 0.05 | X6: 0.1 | Y6: 0.15 | Z6: Comissão % | AA6: 0 | AB6: 0.025 | AC6: 0.05 | AD6: 0.1
A7: Topo de Funil (Indicações/oportunidades) | B7: =SUM(E7:P7) -> 907.5 | E7: =E8*3 -> 37.5 | F7: =F8*3 -> 45 | G7: =G8*3 -> 60 | H7: =H8*3 -> 66 | I7: =I8*3 -> 72 | J7: =J8*3 -> 78 | K7: =K8*3 -> 84 | L7: =L8*3 -> 90 | ... P7: =P8*3 -> 90 | U7: Qtd de Vendas Méd | V7: 3 | W7: 7 | X7: 10 | Y7: 12 | Z7: Qtd de Vendas Méd | AA7: 4 | AB7: 7 | AC7: 12 | AD7: 14
A8: Qtd Visita / Vendedor | B8: =SUM(E8:P8) -> 302.5 | C8: =AVERAGE(E8:P8) -> 25.208333 | D8: 12.5 | E8: =D8 -> 12.5 | F8: 15 | G8: 20 | H8: 22 | I8: 24 | J8: 26 | K8: 28 | L8: 30 | M8: 32 | N8: 33 | O8: 30 | P8: 30 | U8: Faturamento total | V8: =V7*V5 -> 30000 | W8: =W7*W5 -> 70000 | X8: =X7*X5 -> 100000 | Y8: =Y7*Y5 -> 120000 | Z8: Faturamento total | AA8: =AA7*AA5 -> 40000 | AB8: =AB7*AB5 -> 70000 | AC8: =AC7*AC5 -> 120000 | AD8: =AD7*AD5 -> 140000
A9: Total de Propostas | B9: =SUM(E9:P9) -> 605 | C9: =AVERAGE(E9:P9) -> 50.416667 | D9: =E8*E5 -> 25 | E9: =E5*E8 -> 25 | F9: =F5*F8 -> 30 | G9: =G5*G8 -> 40 | H9: =H5*H8 -> 44 | I9: =I5*I8 -> 48 | J9: =J5*J8 -> 52 | K9: =K5*K8 -> 56 | L9: =L5*L8 -> 60 | ... P9: =P5*P8 -> 60 | U9: Fixo | V9: 4000 | W9: =V9 -> 4000 | X9: =W9 -> 4000 | Y9: =X9 -> 4000 | Z9: Fixo | AA9: 5000 | AB9: =AA9 -> 5000 | AC9: =AB9 -> 5000 | AD9: =AC9 -> 5000
A10: Taxa de Conversa Prop/Fech | B10: =SUM(E10:P10) -> 3.84 | C10: =AVERAGE(E10:P10) -> 0.32 | D10: 3.32 | E10: 0.32 | F10: 0.32 | G10: 0.32 | H10: 0.32 | I10: 0.32 | J10: 0.32 | K10: 0.32 | L10: 0.32 | M10: 0.32 | N10: 0.32 | O10: 0.32 | P10: 0.32 | U10: Variável | V10: =V6*V8 -> 0 | W10: =W6*W8 -> 3500 | X10: =X6*X8 -> 10000 | Y10: =Y6*Y8 -> 18000 | Z10: Variável | AA10: =AA6*AA8 -> 0 | AB10: =AB6*AB8 -> 1750 | AC10: =AC6*AC8 -> 6000 | AD10: =AD6*AD8 -> 14000
A11: Total de Fechamentos | B11: =SUM(E11:P11) -> 193.6 | C11: =AVERAGE(D11:P11) -> 15.507692 | D11: =E10*E9 -> 8 | E11: =E10*E9 -> 8 | F11: =F10*F9 -> 9.6 | G11: =G10*G9 -> 12.8 | H11: =H10*H9 -> 14.08 | I11: =I10*I9 -> 15.36 | J11: =J10*J9 -> 16.64 | K11: =K10*K9 -> 17.92 | L11: =L10*L9 -> 19.2 | ... P11: =P10*P9 -> 19.2 | U11: Comissão + Var = R$ | V11: =V9+V8*V6 -> 4000 | W11: =W9+W8*W6 -> 7500 | X11: =X9+X8*X6 -> 14000 | Y11: =Y9+Y8*Y6 -> 22000 | Z11: Comissão + Var = R$ | AA11: =AA9+AA8*AA6 -> 5000 | AB11: =AB9+AB8*AB6 -> 6750 | AC11: =AC9+AC8*AC6 -> 11000 | AD11: =AD9+AD8*AD6 -> 19000
A12: Ticket médio | D12: 7921.7 | E12: =D12 -> 7921.7 | F12: 9000 | G12: 9000 | H12: 10000 | I12: 10000 | J12: 11000 | K12: =J12 -> 11000 | L12: 12000 | M12: =L12 -> 12000 | N12: =M12 -> 12000 | O12: =N12 -> 12000 | P12: =O12 -> 12000 | U12: % Vendas / Faturamento | V12: =V9/V8 -> 0.13333333 | W12: =W9/W8 -> 0.057142857 | X12: =X9/X8 -> 0.04 | Y12: =Y9/Y8 -> 0.033333333 | Z12: % Vendas / Faturamento | AA12: =AA9/AA8 -> 0.125 | AB12: =AB9/AB8 -> 0.071428571 | AC12: =AC9/AC8 -> 0.041666667 | AD12: =AD9/AD8 -> 0.035714286
A13: Faturamento Novas vendas | B13: =SUM(E13:P13) -> 2129933.6 | C13: =AVERAGE(E13:P13) -> 177494.47 | D13: =AVERAGE(E12:P12) -> 10660.142 | E13: =E12*E11 -> 63373.6 | F13: =F12*F11 -> 86400 | G13: =G12*G11 -> 115200 | H13: =H12*H11 -> 140800 | I13: =I12*I11 -> 153600 | J13: =J12*J11 -> 183040 | K13: =K12*K11 -> 197120 | L13: =L12*L11 -> 230400 | ... P13: =P12*P11 -> 230400 | U13: Contribuição R$ | V13: =V8-V11 -> 26000 | W13: =W8-W11 -> 62500 | X13: =X8-X11 -> 86000 | Y13: =Y8-Y11 -> 98000 | Z13: Contribuição R$ | AA13: =AA8-AA11 -> 35000 | AB13: =AB8-AB11 -> 63250 | AC13: =AC8-AC11 -> 109000 | AD13: =AD8-AD11 -> 121000
A14: Parcela 1 | E14: =E13/4 -> 15843.4 | F14: =F13/4 -> 21600 | G14: =G13/4 -> 28800 | H14: =H13/4 -> 35200 | I14: =I13/4 -> 38400 | J14: =J13/4 -> 45760 | K14: =K13/4 -> 49280 | L14: =L13/4 -> 57600 | ... P14: =P13/4 -> 57600 | U14: Entrada Mínima 25% | V14: =25%*V8 -> 7500 | W14: =25%*W8 -> 17500 | X14: =25%*X8 -> 25000 | Y14: =25%*Y8 -> 30000 | Z14: Entrada Mínima 25% | AA14: =25%*AA8 -> 10000 | AB14: =25%*AB8 -> 17500 | AC14: =25%*AC8 -> 30000 | AD14: =25%*AD8 -> 35000
A15: Parcela 2 | F15: =E14 -> 15843.4 | G15: =F14 -> 21600 | H15: =G14 -> 28800 | I15: =H14 -> 35200 | J15: =I14 -> 38400 | K15: =J14 -> 45760 | L15: =K14 -> 49280 | M15: =L14 -> 57600 | ... P15: =O14 -> 57600 | U15: Diferença | V15: =V14-V11 -> 3500 | W15: =W14-W11 -> 10000 | X15: =X14-X11 -> 11000 | Y15: =Y14-Y11 -> 8000 | Z15: Diferença | AA15: =AA14-AA11 -> 5000 | AB15: =AB14-AB11 -> 10750 | AC15: =AC14-AC11 -> 19000 | AD15: =AD14-AD11 -> 16000
A16: Parcela 3 | G16: =F15 -> 15843.4 | H16: =G15 -> 21600 | I16: =H15 -> 28800 | J16: =I15 -> 35200 | K16: =J15 -> 38400 | L16: =K15 -> 45760 | M16: =L15 -> 49280 | N16: =M15 -> 57600 | ... P16: =O15 -> 63360
A17: Parcela 4 | H17: =G16 -> 15843.4 | I17: =H16 -> 21600 | J17: =I16 -> 28800 | K17: =J16 -> 35200 | L17: =K16 -> 38400 | M17: =L16 -> 45760 | N17: =M16 -> 49280 | O17: =N16 -> 57600 | P17: =O16 -> 61440
A18: Total das Parcelas | E18: =SUM(E14:E17) -> 15843.4 | F18: =SUM(F14:F17) -> 37443.4 | G18: =SUM(G14:G17) -> 66243.4 | H18: =SUM(H14:H17) -> 101443.4 | I18: =SUM(I14:I17) -> 124000 | J18: =SUM(J14:J17) -> 148160 | K18: =SUM(K14:K17) -> 168640 | L18: =SUM(L14:L17) -> 191040 | ... P18: =SUM(P14:P17) -> 240000 | AA18: 8 | AB18: 14 | AC18: 24 | AD18: 28
A19: Acumulado de Negócios | D19: 1 | E19: =E11 -> 8 | F19: =F11+E19 -> 17.6 | G19: =G11+F19 -> 30.4 | H19: =H11+G19 -> 44.48 | I19: =I11+H19 -> 59.84 | J19: =J11+I19 -> 76.48 | K19: =K11+J19 -> 94.4 | L19: =L11+K19 -> 113.6 | M19: =M11+L19 -> 134.08 | ... P19: =P11+O19 -> 193.6 | AA19: sobrev | AB19: os import. prim. | AC19: justo correto | AD19: overdelivery
A20: Acumulado de Faturamento | E20: =E13 -> 63373.6 | F20: =F13+E20 -> 149773.6 | G20: =G13+F20 -> 264973.6 | H20: =H13+G20 -> 405773.6 | I20: =I13+H20 -> 559373.6 | J20: =J13+I20 -> 742413.6 | K20: =K13+J20 -> 939533.6 | L20: =L13+K20 -> 1169933.6 | M20: =M13+L20 -> 1415693.6 | ... P20: =P13+O20 -> 2129933.6 | AB20: 10000 | AC20: 19000
A21: Distribuição Faturamento Curva | D21: =AVERAGE(E13:P13) -> 177494.47 | E21: =E4*$D$21 -> 45533.022 | F21: =F4*$D$21 -> 96125.269 | G21: =G4*$D$21 -> 27825.736 | H21: =H4*$D$21 -> 192250.54 | I21: =I4*$D$21 -> 161895.19 | J21: =J4*$D$21 -> 194780.15 | K21: =K4*$D$21 -> 177072.86 | L21: =L4*$D$21 -> 265609.3 | ... P21: =P4*$D$21 -> 227665.11
A22: Comissão (prevista) | D22: 0.05 | E22: =$D$22*E13 -> 3168.68 | F22: =$D$22*F13 -> 4320 | G22: =$D$22*G13 -> 5760 | H22: =$D$22*H13 -> 7040 | I22: =$D$22*I13 -> 7680 | J22: =$D$22*J13 -> 9152 | K22: =$D$22*K13 -> 9856 | L22: =$D$22*L13 -> 11520 | ... P22: =$D$22*P13 -> 11520 | T22: =$D$22*T13 -> 0
A23: Comissão Parcela 1 | D23: =D22 -> 0.05 | E23: =E22/4 -> 792.17 | F23: =F22/4 -> 1080 | G23: =G22/4 -> 1440 | H23: =H22/4 -> 1760 | I23: =I22/4 -> 1920 | J23: =J22/4 -> 2288 | K23: =K22/4 -> 2464 | L23: =L22/4 -> 2880 | ... P23: =P22/4 -> 2880 | T23: =T22/4 -> 0
A24: Comissão Parcela 2 | D24: =D23 -> 0.05 | F24: =E22/4 -> 792.17 | G24: =F22/4 -> 1080 | H24: =G22/4 -> 1440 | I24: =H22/4 -> 1760 | J24: =I22/4 -> 1920 | K24: =J22/4 -> 2288 | L24: =K22/4 -> 2464 | M24: =L22/4 -> 2880 | ... P24: =O22/4 -> 2880 | T24: =S22/4 -> 0
A25: Comissão Parcela 3 | D25: =D24 -> 0.05 | G25: =E22/4 -> 792.17 | H25: =F22/4 -> 1080 | I25: =G22/4 -> 1440 | J25: =H22/4 -> 1760 | K25: =I22/4 -> 1920 | L25: =J22/4 -> 2288 | M25: =K22/4 -> 2464 | N25: =L22/4 -> 2880 | ... P25: =N22/4 -> 3168 | T25: =R22/4 -> 0
A26: Comissão Parcela 4 | D26: =D25 -> 0.05 | H26: =E22/4 -> 792.17 | I26: =F22/4 -> 1080 | J26: =G22/4 -> 1440 | K26: =H22/4 -> 1760 | L26: =I22/4 -> 1920 | M26: =J22/4 -> 2288 | N26: =K22/4 -> 2464 | O26: =L22/4 -> 2880 | P26: =M22/4 -> 3072 | T26: =Q22/4 -> 0
A27: Total de Comissão (P1 + P2 + P3 + P4) | E27: =SUM(E23:E26) -> 792.17 | F27: =SUM(F23:F26) -> 1872.17 | G27: =SUM(G23:G26) -> 3312.17 | H27: =SUM(H23:H26) -> 5072.17 | I27: =SUM(I23:I26) -> 6200 | J27: =SUM(J23:J26) -> 7408 | K27: =SUM(K23:K26) -> 8432 | L27: =SUM(L23:L26) -> 9552 | ... P27: =SUM(P23:P26) -> 12000 | T27: =SUM(T23:T26) -> 0
A28: % Comissão / Faturamento | E28: =E27/E18 -> 0.05 | F28: =F27/F18 -> 0.05 | G28: =G27/G18 -> 0.05 | H28: =H27/H18 -> 0.05 | I28: =I27/I18 -> 0.05 | J28: =J27/J18 -> 0.05 | K28: =K27/K18 -> 0.05 | L28: =L27/L18 -> 0.05 | ... P28: =P27/P18 -> 0.05
A29: Imposto sobre o Faturamento | C29: Alíquota | D29: 0.16 | E29: 0.12798836 | F29: 0.13048797 | G29: 0.13235981 | H29: 0.13442758 | I29: 0.13623606 | J29: 0.13803785 | K29: 0.13997972 | L29: 0.14506742 | M29: 0.15081251 | N29: 0.15635105 | O29: 0.16086615 | P29: 0.16495483
A30: Imposto (prevista) | D30: 0.1
A31: Imposto Parcela 1 | D31: =D30 -> 0.1
A32: Imposto Parcela 2 | D32: =D31 -> 0.1
A33: Imposto Parcela 3 | D33: =D32 -> 0.1
A34: Imposto Parcela 4 | D34: =D33 -> 0.1
A35: Total Imposto (P1 + P2 + P3 + P4) | D35: =D34 -> 0.1
A36: Custo de Serviço Prestado | D36: =((180)+(675/5)+700/10+500/10) -> 435 | E36: =$D$36*E11 -> 3480 | F36: =$D$36*F11 -> 4176 | G36: =$D$36*G11 -> 5568 | H36: =$D$36*H11 -> 6124.8 | I36: =$D$36*I11 -> 6681.6 | J36: =$D$36*J11 -> 7238.4 | K36: =$D$36*K11 -> 7795.2 | L36: =$D$36*L11 -> 8352 | ... P36: =$D$36*P11 -> 8352
D37: % | E37: =E36/E18 -> 0.21964982 | F37: =F36/F18 -> 0.11152833 | G37: =G36/G18 -> 0.084053657 | H37: =H36/H18 -> 0.060376525 | I37: =I36/I18 -> 0.053883871 | J37: =J36/J18 -> 0.048855292 | K37: =K36/K18 -> 0.046223909 | L37: =L36/L18 -> 0.043718593 | ... P37: =P36/P18 -> 0.0348
A38: Margem de Lucro % (custo, comissão, imposto) | C38: 0.4 | D38: 0.62 | E38: =100%-E37-E28-E29 -> 0.60236181 | F38: =100%-F37-F28-F29 -> 0.70798369 | G38: =100%-G37-G28-G29 -> 0.73358653 | H38: =100%-H37-H28-H29 -> 0.75519589 | I38: =100%-I37-I28-I29 -> 0.75988007 | J38: =100%-J37-J28-J29 -> 0.76310686 | K38: =100%-K37-K28-K29 -> 0.76379637 | L38: =100%-L37-L28-L29 -> 0.76121399 | ... P38: =100%-P37-P28-P29 -> 0.75024517
A39: Lucro Bruto Oper/Serviço | B39: =SUM(E39:P39) -> 1596452.8 | C39: =AVERAGE(E39:P39) -> 133037.73 | D39: =D38*D13 -> 6609.2878 | E39: =E38*E13 -> 38173.837 | F39: =F38*F13 -> 61169.791 | G39: =G38*G13 -> 84509.168 | H39: =H38*H13 -> 106331.58 | I39: =I38*I13 -> 116717.58 | J39: =J38*J13 -> 139679.08 | K39: =K38*K13 -> 150559.54 | ... P39: =P38*P13 -> 172856.49
A40: Margens dos Projetos | B40: % | C40: Qtd. Mensal | D40: 1 parcela | E40: =E39/4 -> 9543.4591 | F40: =F39/4 -> 15292.448 | G40: =G39/4 -> 21127.292 | H40: =H39/4 -> 26582.895 | I40: =I39/4 -> 29179.395 | J40: =J39/4 -> 34919.77 | K40: =K39/4 -> 37639.885 | L40: =L39/4 -> 43845.926 | ... P40: =P39/4 -> 43214.122
...

Sheet Projeção Projetos Joni
A1: Projetos Consultoria
A2: Mês | E2: Total | F2: Média | H2: Referência | I2: 1 | J2: 2 | K2: 3 | L2: 4 | M2: 5 | N2: 6 | O2: 7 | P2: 8 | Q2: 9 | R2: 10 | S2: 11 | T2: 12
A3: Total de Fechamentos | E3: ='Projeção Biel Ajustada'!B11 -> 193.6 | F3: ='Projeção Biel Ajustada'!C11 -> 15.507692 | H3: ='Projeção Biel Ajustada'!D11 -> 8 | I3: ='Projeção Biel Ajustada'!E11 -> 8 | J3: ='Projeção Biel Ajustada'!F11 -> 9.6 | K3: ='Projeção Biel Ajustada'!G11 -> 12.8 | L3: ='Projeção Biel Ajustada'!H11 -> 14.08 | M3: ='Projeção Biel Ajustada'!I11 -> 15.36 | N3: ='Projeção Biel Ajustada'!J11 -> 16.64 | O3: ='Projeção Biel Ajustada'!K11 -> 17.92 | ... T3: ='Projeção Biel Ajustada'!P11 -> 19.2
A4: Ticket médio | H4: ='Projeção Biel Ajustada'!E10 -> 0.32 | I4: 9000 | J4: 9000 | K4: 9000 | L4: 9000 | M4: 9000 | N4: 9000 | O4: 9000 | P4: 9000 | Q4: 9000 | R4: 9000 | S4: 9000 | T4: 9000
A5: Acumulado de Negócios | H5: 1 | I5: =I3 -> 8 | J5: =J3+I5 -> 17.6 | K5: =K3+J5 -> 30.4 | L5: =L3+K5 -> 44.48 | M5: =M3+L5 -> 59.84 | N5: =N3+M5 -> 76.48 | O5: =O3+N5 -> 94.4 | P5: =P3+O5 -> 113.6 | Q5: =Q3+P5 -> 134.08 | ... T5: =T3+S5 -> 193.6
A6: Serviços | I6: =I4*I3/$B$15 -> 9.7156627 | J6: =J4*J3/$B$15 -> 11.658795 | K6: =K4*K3/$B$15 -> 15.54506 | L6: =L4*L3/$B$15 -> 17.099566 | M6: =M4*M3/$B$15 -> 18.654072 | N6: =N4*N3/$B$15 -> 20.208578 | O6: =O4*O3/$B$15 -> 21.763084 | P6: =P4*P3/$B$15 -> 23.31759 | ... T6: =T4*T3/$B$15 -> 23.31759
A7: Serviços Acumulados | I7: =I6 -> 9.7156627 | J7: =I7+J6 -> 21.374458 | K7: =J7+K6 -> 36.919518 | L7: =K7+L6 -> 54.019084 | M7: =L7+M6 -> 72.673157 | N7: =M7+N6 -> 92.881735 | O7: =N7+O6 -> 114.64482 | P7: =O7+P6 -> 137.96241 | Q7: =P7+Q6 -> 162.83451 | ... T7: =S7+T6 -> 235.11904
A8: Custo de Serviço Prestado | B8: TICKET | C8: Taxa de QNTD | D8: PREPARAÇÃO | E8: TEMPO CAMPO (DIAS) | F8: TEMPO PROJETO (DIAS) | G8: TEMPO REVISÃO (DIAS) | H8: TICKET/TEMPO
A9: Disponibilidade Carga + PE | B9: 9000 | C9: =27/56 -> 0.48214286 | D9: 3 | E9: 6 | F9: 2 | G9: 1 | H9: =B9/SUM(D9:G9) -> 750 | I9: =$C9*I$6 -> 4.6843373 | J9: =$C9*J$6 -> 5.6212048 | K9: =$C9*K$6 -> 7.4949398 | L9: =$C9*L$6 -> 8.2444337 | M9: =$C9*M$6 -> 8.9939277 | N9: =$C9*N$6 -> 9.7434217 | O9: =$C9*O$6 -> 10.492916 | P9: =$C9*P$6 -> 11.24241 | ... T9: =$C9*T$6 -> 11.24241
A10: Laudo Instalações + G. Risco | B10: 7000 | C10: =15/56 -> 0.26785714 | D10: 3 | E10: 1 | F10: 5 | G10: 2 | H10: =B10/SUM(D10:G10) -> 636.36364 | I10: =$C10*I$6 -> 2.6024096 | J10: =$C10*J$6 -> 3.1228916 | K10: =$C10*K$6 -> 4.1638554 | L10: =$C10*L$6 -> 4.580241 | M10: =$C10*M$6 -> 4.9966265 | N10: =$C10*N$6 -> 5.413012 | O10: =$C10*O$6 -> 5.8293976 | P10: =$C10*P$6 -> 6.2457831 | ... T10: =$C10*T$6 -> 6.2457831
A11: Inspeção Carregadores (+/- 5 unid) | B11: 2500 | C11: =4/56 -> 0.071428571 | D11: 3 | E11: 1 | F11: 1 | G11: 1 | H11: =B11/SUM(D11:G11) -> 416.66667 | I11: =$C11*I$6 -> 0.6939759 | J11: =$C11*J$6 -> 0.83277108 | K11: =$C11*K$6 -> 1.1103614 | L11: =$C11*L$6 -> 1.2213976 | M11: =$C11*M$6 -> 1.3324337 | N11: =$C11*N$6 -> 1.4434699 | O11: =$C11*O$6 -> 1.554506 | P11: =$C11*P$6 -> 1.6655422 | ... T11: =$C11*T$6 -> 1.6655422
A12: Projeto CDM | B12: 5000 | C12: =4/56 -> 0.071428571 | D12: 3 | E12: 1 | F12: 5 | G12: 2 | H12: =B12/SUM(D12:G12) -> 454.54545 | I12: =$C12*I$6 -> 0.6939759 | J12: =$C12*J$6 -> 0.83277108 | K12: =$C12*K$6 -> 1.1103614 | L12: =$C12*L$6 -> 1.2213976 | M12: =$C12*M$6 -> 1.3324337 | N12: =$C12*N$6 -> 1.4434699 | O12: =$C12*O$6 -> 1.554506 | P12: =$C12*P$6 -> 1.6655422 | ... T12: =$C12*T$6 -> 1.6655422
A13: Projeto Eletrocalha + Botão | B13: 5000 | C13: =5/56 -> 0.089285714 | D13: 3 | E13: 2 | F13: 15 | G13: 2 | H13: =B13/SUM(D13:G13) -> 227.27273 | I13: =$C13*I$6 -> 0.86746988 | J13: =$C13*J$6 -> 1.0409639 | K13: =$C13*K$6 -> 1.3879518 | L13: =$C13*L$6 -> 1.526747 | M13: =$C13*M$6 -> 1.6655422 | N13: =$C13*N$6 -> 1.8043373 | O13: =$C13*O$6 -> 1.9431325 | P13: =$C13*P$6 -> 2.0819277 | ... T13: =$C13*T$6 -> 2.0819277
A14: Laudo SPDA + Viabilidade Estr. + Proj | B14: 12000 | C14: =1/56 -> 0.017857143 | D14: 3 | E14: 8 | F14: 15 | G14: 2 | H14: =B14/SUM(D14:G14) -> 428.57143 | I14: =$C14*I$6 -> 0.17349398 | J14: =$C14*J$6 -> 0.20819277 | K14: =$C14*K$6 -> 0.27759036 | L14: =$C14*L$6 -> 0.3053494 | M14: =$C14*M$6 -> 0.33310843 | N14: =$C14*N$6 -> 0.36086747 | O14: =$C14*O$6 -> 0.38862651 | P14: =$C14*P$6 -> 0.41638554 | ... T14: =$C14*T$6 -> 0.41638554
B15: =SUMPRODUCT(B9:B14,C9:C14) -> 7410.7143 | C15: =SUM(C9:C14) -> 1
A16: Custo de Serviço Prestado | B16: TICKET | C16: Taxa de QNTD | D16: PREPARAÇÃO | E16: CAPACIDADE CAMPO | F16: CAPACIDADE PROJETO | G16: TEMPO REVISÃO (DIAS) | H16: OUTROS (DIAS)
A17: Disponibilidade Carga | B17: 9000 | C17: =27/56 -> 0.48214286 | D17: 3 | E17: =20/E9*4 -> 13.333333 | F17: =20/F9 -> 10 | G17: =20/G9 -> 20 | I17: =$C17*I$6 -> 4.6843373 | J17: =$C17*J$6 -> 5.6212048 | K17: =$C17*K$6 -> 7.4949398 | L17: =$C17*L$6 -> 8.2444337 | M17: =$C17*M$6 -> 8.9939277 | N17: =$C17*N$6 -> 9.7434217 | O17: =$C17*O$6 -> 10.492916 | P17: =$C17*P$6 -> 11.24241 | ... T17: =$C17*T$6 -> 11.24241
A18: Laudo Instalações + G. Risco | B18: 7000 | C18: =15/56 -> 0.26785714 | D18: 3 | E18: =20/E10 -> 20 | F18: =20/F10 -> 4 | G18: =20/G10 -> 10 | I18: =$C18*I$6 -> 2.6024096 | J18: =$C18*J$6 -> 3.1228916 | K18: =$C18*K$6 -> 4.1638554 | L18: =$C18*L$6 -> 4.580241 | M18: =$C18*M$6 -> 4.9966265 | N18: =$C18*N$6 -> 5.413012 | O18: =$C18*O$6 -> 5.8293976 | P18: =$C18*P$6 -> 6.2457831 | ... T18: =$C18*T$6 -> 6.2457831
A19: Inspeção Carregadores (+/- 5 unid) | B19: 2500 | C19: =4/56 -> 0.071428571 | D19: 3 | E19: =20/E11 -> 20 | F19: =20/F11 -> 20 | G19: =20/G11 -> 20 | I19: =$C19*I$6 -> 0.6939759 | J19: =$C19*J$6 -> 0.83277108 | K19: =$C19*K$6 -> 1.1103614 | L19: =$C19*L$6 -> 1.2213976 | M19: =$C19*M$6 -> 1.3324337 | N19: =$C19*N$6 -> 1.4434699 | O19: =$C19*O$6 -> 1.554506 | P19: =$C19*P$6 -> 1.6655422 | ... T19: =$C19*T$6 -> 1.6655422
A20: Projeto CDM | B20: 5000 | C20: =4/56 -> 0.071428571 | D20: 3 | E20: =20/E12 -> 20 | F20: =20/F12 -> 4 | G20: =20/G12 -> 10 | H20: 40 | I20: =$C20*I$6 -> 0.6939759 | J20: =$C20*J$6 -> 0.83277108 | K20: =$C20*K$6 -> 1.1103614 | L20: =$C20*L$6 -> 1.2213976 | M20: =$C20*M$6 -> 1.3324337 | N20: =$C20*N$6 -> 1.4434699 | O20: =$C20*O$6 -> 1.554506 | P20: =$C20*P$6 -> 1.6655422 | ... T20: =$C20*T$6 -> 1.6655422
A21: Projeto Eletrocalha | B21: 5000 | C21: =5/56 -> 0.089285714 | D21: 3 | E21: =20/E13 -> 10 | F21: =20/F13 -> 1.3333333 | G21: =20/G13 -> 10 | I21: =$C21*I$6 -> 0.86746988 | J21: =$C21*J$6 -> 1.0409639 | K21: =$C21*K$6 -> 1.3879518 | L21: =$C21*L$6 -> 1.526747 | M21: =$C21*M$6 -> 1.6655422 | N21: =$C21*N$6 -> 1.8043373 | O21: =$C21*O$6 -> 1.9431325 | P21: =$C21*P$6 -> 2.0819277 | ... T21: =$C21*T$6 -> 2.0819277
A22: Laudo SPDA + Viabilidade Estr. + Proj | B22: 12000 | C22: =1/56 -> 0.017857143 | D22: 3 | E22: =20/E14 -> 2.5 | F22: =20/F14 -> 1.3333333 | G22: =20/G14 -> 10 | I22: =$C22*I$6 -> 0.17349398 | J22: =$C22*J$6 -> 0.20819277 | K22: =$C22*K$6 -> 0.27759036 | L22: =$C22*L$6 -> 0.3053494 | M22: =$C22*M$6 -> 0.33310843 | N22: =$C22*N$6 -> 0.36086747 | O22: =$C22*O$6 -> 0.38862651 | P22: =$C22*P$6 -> 0.41638554 | ... T22: =$C22*T$6 -> 0.41638554
A24: CUSTO EXECUÇÃO / PESSOA | B24: /ANO | C24: /MES
A25: EPI | B25: 1000 | C25: =B25/12 -> 83.333333
A26: CALIBRAÇÃO | B26: 12000 | C26: =B26/12 -> 1000
A27: FERRAMENTA | B27: =(100*5+500+350+300+50+45+100*5*12)/5 -> 1549 | C27: =B27/12 -> 129.08333
A28: TOTAL | B28: =SUM(B25:B27) -> 14549 | C28: =B28/12 -> 1212.4167

Sheet Projeção Base
A1: Faturamento Consultoria
A2: Mês | B2: Total | C2: Média | D2: Referência | E2: 1 | F2: 2 | G2: 3 | H2: 4 | I2: 5 | J2: 6 | K2: 7 | L2: 8 | M2: 9 | N2: 10 | O2: 11 | P2: 12
A3: Curva Faturamento R$ | B3: =SUM(E3:P3) -> 2008800 | C3: =AVERAGE(E3:P3) -> 167400 | E3: ='Premissas gerais'!O5 -> 42943.468 | F3: ='Premissas gerais'!P5 -> 90658.432 | G3: ='Premissas gerais'!Q5 -> 26243.23 | H3: ='Premissas gerais'!R5 -> 181316.86 | I3: ='Premissas gerais'!S5 -> 152687.89 | J3: ='Premissas gerais'!T5 -> 183702.61 | K3: ='Premissas gerais'!U5 -> 167002.38 | L3: ='Premissas gerais'!V5 -> 250503.56 | ... P3: ='Premissas gerais'!Z5 -> 214717.34
A4: Curva Faturamento % | B4: 1 | C4: =AVERAGE(E4:P4) -> 1 | E4: =E3/$C$3 -> 0.25653207 | F4: =F3/$C$3 -> 0.5415677 | G4: =G3/$C$3 -> 0.1567696 | H4: =H3/$C$3 -> 1.0831354 | I4: =I3/$C$3 -> 0.91211401 | J4: =J3/$C$3 -> 1.0973872 | K4: =K3/$C$3 -> 0.9976247 | L4: =L3/$C$3 -> 1.4964371 | ... P4: =P3/$C$3 -> 1.2826603
A5: Qtd Vendedores | B5: =C5 -> 2 | C5: =AVERAGE(E5:P5) -> 2 | D5: 2 | E5: =D5 -> 2 | F5: =E5 -> 2 | G5: =F5 -> 2 | H5: =G5 -> 2 | I5: =H5 -> 2 | J5: =I5 -> 2 | K5: 2 | L5: =K5 -> 2 | M5: =L5 -> 2 | N5: =M5 -> 2 | O5: =N5 -> 2 | P5: =O5 -> 2
A6: Qtd Visita / Vendedor | B6: =SUM(E6:P6) -> 288.5 | C6: =AVERAGE(E6:P6) -> 24.041667 | D6: 12.5 | E6: =D6 -> 12.5 | F6: 15 | G6: 17 | H6: 20 | I6: 22 | J6: 25 | K6: 27 | L6: 30 | M6: =L6 -> 30 | N6: =M6 -> 30 | O6: =N6 -> 30 | P6: =O6 -> 30
A7: Total de Propostas | B7: =SUM(E7:P7) -> 577 | C7: =AVERAGE(E7:P7) -> 48.083333 | D7: =E6*E5 -> 25 | E7: =E5*E6 -> 25 | F7: =F5*F6 -> 30 | G7: =G5*G6 -> 34 | H7: =H5*H6 -> 40 | I7: =I5*I6 -> 44 | J7: =J5*J6 -> 50 | K7: =K5*K6 -> 54 | L7: =L5*L6 -> 60 | ... P7: =P5*P6 -> 60
A8: Taxa de Conversa Prop/Fech | B8: =SUM(E8:P8) -> 3.84 | C8: =AVERAGE(E8:P8) -> 0.32 | D8: =4/12.5 -> 0.32 | E8: =D8 -> 0.32 | F8: 0.32 | G8: 0.32 | H8: 0.32 | I8: 0.32 | J8: 0.32 | K8: 0.32 | L8: 0.32 | M8: 0.32 | N8: 0.32 | O8: 0.32 | P8: 0.32
A9: Total de Fechamentos | B9: =SUM(E9:P9) -> 184.64 | C9: =AVERAGE(D9:P9) -> 14.818462 | D9: =E8*E7 -> 8 | E9: =E8*E7 -> 8 | F9: =F8*F7 -> 9.6 | G9: =G8*G7 -> 10.88 | H9: =H8*H7 -> 12.8 | I9: =I8*I7 -> 14.08 | J9: =J8*J7 -> 16 | K9: =K8*K7 -> 17.28 | L9: =L8*L7 -> 19.2 | ... P9: =P8*P7 -> 19.2
A10: Ticket médio | D10: 7921.7 | E10: =D10 -> 7921.7 | F10: 9000 | G10: 9000 | H10: 10000 | I10: 10000 | J10: 11000 | K10: =J10 -> 11000 | L10: 12000 | M10: =L10 -> 12000 | N10: =M10 -> 12000 | O10: =N10 -> 12000 | P10: =O10 -> 12000
A11: Faturamento Novas vendas | B11: =SUM(E11:P11) -> 2034573.6 | C11: =AVERAGE(E11:P11) -> 169547.8 | D11: =AVERAGE(E10:P10) -> 10660.142 | E11: =E10*E9 -> 63373.6 | F11: =F10*F9 -> 86400 | G11: =G10*G9 -> 97920 | H11: =H10*H9 -> 128000 | I11: =I10*I9 -> 140800 | J11: =J10*J9 -> 176000 | K11: =K10*K9 -> 190080 | L11: =L10*L9 -> 230400 | ... P11: =P10*P9 -> 230400
A12: Acumulado de Negócios | D12: 1 | E12: =E9 -> 8 | F12: =F9+E12 -> 17.6 | G12: =G9+F12 -> 28.48 | H12: =H9+G12 -> 41.28 | I12: =I9+H12 -> 55.36 | J12: =J9+I12 -> 71.36 | K12: =K9+J12 -> 88.64 | L12: =L9+K12 -> 107.84 | M12: =M9+L12 -> 127.04 | ... P12: =P9+O12 -> 184.64
A13: Acumulado de Faturamento | E13: =E11 -> 63373.6 | F13: =F11+E13 -> 149773.6 | G13: =G11+F13 -> 247693.6 | H13: =H11+G13 -> 375693.6 | I13: =I11+H13 -> 516493.6 | J13: =J11+I13 -> 692493.6 | K13: =K11+J13 -> 882573.6 | L13: =L11+K13 -> 1112973.6 | M13: =M11+L13 -> 1343373.6 | ... P13: =P11+O13 -> 2034573.6
A14: Distribuição Faturamento Curva | D14: =AVERAGE(E11:P11) -> 169547.8 | E14: =E4*$D$14 -> 43494.448 | F14: =F4*$D$14 -> 91821.611 | G14: =G4*$D$14 -> 26579.94 | H14: =H4*$D$14 -> 183643.22 | I14: =I4*$D$14 -> 154646.92 | J14: =J4*$D$14 -> 186059.58 | K14: =K4*$D$14 -> 169145.07 | L14: =L4*$D$14 -> 253717.61 | ... P14: =P4*$D$14 -> 217472.24
A15: Margem de Lucro % (custo, comissão, imposto) | C15: 0.4 | D15: 0.62 | E15: =D15 -> 0.62 | F15: =E15 -> 0.62 | G15: =F15 -> 0.62 | H15: =G15 -> 0.62 | I15: =H15 -> 0.62 | J15: =I15 -> 0.62 | K15: =J15 -> 0.62 | L15: =K15 -> 0.62 | ... P15: =O15 -> 0.62 | R15: =900/7000 -> 0.12857143
A16: Lucro Bruto Oper/Serviço | B16: =SUM(E16:P16) -> 1261435.6 | C16: =AVERAGE(E16:P16) -> 105119.64 | D16: =D15*D11 -> 6609.2878 | E16: =E15*E11 -> 39291.632 | F16: =F15*F11 -> 53568 | G16: =G15*G11 -> 60710.4 | H16: =H15*H11 -> 79360 | I16: =I15*I11 -> 87296 | J16: =J15*J11 -> 109120 | K16: =K15*K11 -> 117849.6 | ... P16: =P15*P11 -> 142848
A17: Margens dos Projetos | B17: % | C17: Qtd. Mensal | D17: 1 parcela | E17: =E16/4 -> 9822.908 | F17: =F16/4 -> 13392 | G17: =G16/4 -> 15177.6 | H17: =H16/4 -> 19840 | I17: =I16/4 -> 21824 | J17: =J16/4 -> 27280 | K17: =K16/4 -> 29462.4 | L17: =L16/4 -> 35712 | ... P17: =P16/4 -> 35712
A18: Disponibilidade | B18: =5125/8000 -> 0.640625 | C18: =3*4.28 -> 12.84 | D18: 2 parcela | E18: 0 | F18: =E17 -> 9822.908 | G18: =F17 -> 13392 | H18: =G17 -> 15177.6 | I18: =H17 -> 19840 | J18: =I17 -> 21824 | K18: =J17 -> 27280 | L18: =K17 -> 29462.4 | M18: =L17 -> 35712 | ... P18: =O17 -> 35712
A19: Projeto | B19: =0.55 -> 0.55 | D19: 3 parcela | E19: 0 | G19: =F18 -> 9822.908 | H19: =G18 -> 13392 | I19: =H18 -> 15177.6 | J19: =I18 -> 19840 | K19: =J18 -> 21824 | L19: =K18 -> 27280 | M19: =L18 -> 29462.4 | N19: =M18 -> 35712 | ... P19: =O18 -> 35712
A20: Laudo + G. Risco | B20: =59% -> 0.59 | D20: 4 parcela | E20: 0 | H20: =G19 -> 9822.908 | I20: =H19 -> 13392 | J20: =I19 -> 15177.6 | K20: =J19 -> 19840 | L20: =K19 -> 21824 | M20: =L19 -> 27280 | N20: =M19 -> 29462.4 | O20: =N19 -> 35712 | P20: =O19 -> 35712
D21: Total Lucro Bruto Novo | E21: =SUM(E17:E20) -> 9822.908 | F21: =SUM(F17:F20) -> 23214.908 | G21: =SUM(G17:G20) -> 38392.508 | H21: =SUM(H17:H20) -> 58232.508 | I21: =SUM(I17:I20) -> 70233.6 | J21: =SUM(J17:J20) -> 84121.6 | K21: =SUM(K17:K20) -> 98406.4 | L21: =SUM(L17:L20) -> 114278.4 | ... P21: =SUM(P17:P20) -> 142848
B22: =B24/B11 -> 0.7160732 | D22: Lucro previsto 2025 | E22: 58000 | F22: 39000 | G22: 25000 | H22: 5500
A23: Faturamento XPE | B23: =SUM(E23:P23) -> 2230618.8 | D23: 28000 | E23: =SUM(E21:E22)/E15+$D$23 -> 137391.79 | F23: =SUM(F21:F22)/F15+$D$23 -> 128346.63 | G23: =SUM(G21:G22)/G15+$D$23 -> 130245.98 | H23: =SUM(H21:H22)/H15+$D$23 -> 130794.37 | I23: =SUM(I21:I22)/I15+$D$23 -> 141280 | J23: =SUM(J21:J22)/J15+$D$23 -> 163680 | K23: =SUM(K21:K22)/K15+$D$23 -> 186720 | L23: =SUM(L21:L22)/L15+$D$23 -> 212320 | ... P23: =SUM(P21:P22)/P15+$D$23 -> 258400
A24: Margem de Contribuição Prevista | B24: =SUM(E24:P24) -> 1456903.6 | C24: Receita BRA + outros | D24: =28000*0.84 -> 23520 | E24: =$D$24+E22+E21 -> 91342.908 | F24: =$D$24+F22+F21 -> 85734.908 | G24: =$D$24+G22+G21 -> 86912.508 | H24: =$D$24+H22+H21 -> 87252.508 | I24: =$D$24+I22+I21 -> 93753.6 | J24: =$D$24+J22+J21 -> 107641.6 | K24: =$D$24+K22+K21 -> 121926.4 | L24: =$D$24+L22+L21 -> 137798.4 | ... P24: =$D$24+P22+P21 -> 166368
A25: Custo Fixo Total | B25: ='Premissas gerais'!B99 -> 85921 | E25: =B25 -> 85921 | F25: =E25 -> 85921 | G25: =F25 -> 85921 | H25: =G25 -> 85921 | I25: =H25 -> 85921 | J25: =I25 -> 85921 | K25: =J25 -> 85921 | L25: =K25 -> 85921 | M25: =L25 -> 85921 | ... P25: =O25 -> 85921
A26: Lucro Líquido Mensal | C26: =D27/B23 -> 0.19091188 | D26: =AVERAGE(E26:P26) -> 35487.636 | E26: =E24-E25 -> 5421.908 | F26: =F24-F25 -> -186.092 | G26: =G24-G25 -> 991.508 | H26: =H24-H25 -> 1331.508 | I26: =I24-I25 -> 7832.6 | J26: =J24-J25 -> 21720.6 | K26: =K24-K25 -> 36005.4 | L26: =L24-L25 -> 51877.4 | ... P26: =P24-P25 -> 80447
A27: Lucro Líquido Acumulado | D27: =P27 -> 425851.63 | E27: =E26+C27 -> 5421.908 | F27: =F26+E27 -> 5235.816 | G27: =G26+F27 -> 6227.324 | H27: =H26+G27 -> 7558.832 | I27: =I26+H27 -> 15391.432 | J27: =J26+I27 -> 37112.032 | K27: =K26+J27 -> 73117.432 | L27: =L26+K27 -> 124994.83 | M27: =M26+L27 -> 190760.23 | ... P27: =P26+O27 -> 425851.63
A31: MRR - Plataforma | E31: 0 | F31: 0 | G31: 1
A32: Ticket médio | D32: 100 | E32: =D32 -> 100 | F32: =E32 -> 100 | G32: =F32 -> 100 | H32: =G32 -> 100 | I32: =H32 -> 100 | J32: =I32 -> 100 | K32: =J32 -> 100 | L32: =K32 -> 100 | ... P32: =O32 -> 100
A33: Taxa de conversão | D33: 0.2 | E33: =D33 -> 0.2 | F33: =E33 -> 0.2 | G33: =F33 -> 0.2 | H33: =G33 -> 0.2 | I33: =H33 -> 0.2 | J33: =I33 -> 0.2 | K33: =J33 -> 0.2 | L33: =K33 -> 0.2 | ... P33: =O33 -> 0.2
A34: qtd. Novos clientes | E34: =E33*E9 -> 1.6 | F34: =F33*F9 -> 1.92 | G34: =G33*G9 -> 2.176 | H34: =H33*H9 -> 2.56 | I34: =I33*I9 -> 2.816 | J34: =J33*J9 -> 3.2 | K34: =K33*K9 -> 3.456 | L34: =L33*L9 -> 3.84 | ... P34: =P33*P9 -> 3.84
A35: Acumulado de Clientes | D35: 03 meses sem plataforma | E35: 0 | F35: 0 | G35: 0 | H35: =H34+G35 -> 2.56 | I35: =I34+H35 -> 5.376 | J35: =J34+I35 -> 8.576 | K35: =K34+J35 -> 12.032 | L35: =L34+K35 -> 15.872 | M35: =M34+L35 -> 19.712 | N35: =N34+M35 -> 23.552 | O35: =O34+N35 -> 27.392 | P35: =P34+O35 -> 31.232
A36: Faturamento Mensal | E36: =E35*E32 -> 0 | F36: =F35*F32 -> 0 | G36: =G35*G32 -> 0 | H36: =H35*H32 -> 256 | I36: =I35*I32 -> 537.6 | J36: =J35*J32 -> 857.6 | K36: =K35*K32 -> 1203.2 | L36: =L35*L32 -> 1587.2 | ... P36: =P35*P32 -> 3123.2
A37: Acumulado anual | E37: =E36 -> 0 | F37: =F36+E37 -> 0 | G37: =G36+F37 -> 0 | H37: =H36+G37 -> 256 | I37: =I36+H37 -> 793.6 | J37: =J36+I37 -> 1651.2 | K37: =K36+J37 -> 2854.4 | L37: =L36+K37 -> 4441.6 | M37: =M36+L37 -> 6412.8 | ... P37: =P36+O37 -> 14630.4
A40: MRR - Ger. Carregadores Ticket | D40: 200 | E40: =D40 -> 200 | F40: =E40 -> 200 | G40: =F40 -> 200 | H40: =G40 -> 200 | I40: =H40 -> 200 | J40: =I40 -> 200 | K40: =J40 -> 200 | L40: =K40 -> 200 | ... P40: =O40 -> 200
A41: Taxa de conversão | D41: 0.1 | E41: =D41 -> 0.1 | F41: =E41 -> 0.1 | G41: =F41 -> 0.1 | H41: =G41 -> 0.1 | I41: =H41 -> 0.1 | J41: =I41 -> 0.1 | K41: =J41 -> 0.1 | L41: =K41 -> 0.1 | ... P41: =O41 -> 0.1
A42: qtd. Novos clientes | E42: =E41*E9 -> 0.8 | F42: =F41*F9 -> 0.96 | G42: =G41*G9 -> 1.088 | H42: =H41*H9 -> 1.28 | I42: =I41*I9 -> 1.408 | J42: =J41*J9 -> 1.6 | K42: =K41*K9 -> 1.728 | L42: =L41*L9 -> 1.92 | ... P42: =P41*P9 -> 1.92
A43: Acumulado de Clientes | E43: 0 | F43: 0 | G43: 0 | H43: 0 | I43: 0 | J43: =J42+I43 -> 1.6 | K43: =K42+J43 -> 3.328 | L43: =L42+K43 -> 5.248 | M43: =M42+L43 -> 7.168 | N43: =N42+M43 -> 9.088 | O43: =O42+N43 -> 11.008 | P43: =P42+O43 -> 12.928
A44: Faturamento Mensal | E44: =B43*B40 -> 0 | F44: =C43*C40 -> 0 | G44: =D43*D40 -> 0 | H44: =E43*E40 -> 0 | I44: =F43*F40 -> 0 | J44: =J43*J40 -> 320 | K44: =K43*K40 -> 665.6 | L44: =L43*L40 -> 1049.6 | M44: =M43*M40 -> 1433.6 | N44: =N43*N40 -> 1817.6 | O44: =O43*O40 -> 2201.6 | P44: =P43*P40 -> 2585.6 | Q44: =Q43*Q40 -> 0 | ... S44: =S43*S40 -> 0
A45: Acumulado anual | E45: =E44 -> 0 | F45: =F44 -> 0 | G45: =G44 -> 0 | H45: =H44 -> 0 | I45: =I44+H45 -> 0 | J45: =J44+I45 -> 320 | K45: =K44+J45 -> 985.6 | L45: =L44+K45 -> 2035.2 | M45: =M44+L45 -> 3468.8 | N45: =N44+M45 -> 5286.4 | O45: =O44+N45 -> 7488 | P45: =P44+O45 -> 10073.6 | ... S45: =S44+R45 -> 10073.6
...

Sheet Reformas
A1: Investimentos Infraestrutura
A3: Climatização das duas salas
A4: Ar-condicionado 24.000 btu
A5: Cobertura das paredes com acabamento
A6: Outros custos da sala
A8: Expansão e reorganização das estações de trabalho
A9: Levantar necessidades de cadeiras e mesas e extensões
A13: Almoxarifado/organização de materiais de serviços
A14: fazer orçamento do que precisa para ficar tudo organizado e gerível visualmente.
A18: Sala de Refeição e Recepção
A19: Cobertura + detalhes verde + móvel e adesivos
A20: microondas
... A33: Melhorar condições de trabalho individual
A34: Jonildo | B34: Monitor
A35: Paulo Araújo | B35: Monitor
A36: Kalebe | B36: Monitor
A40: Lista de compras e materiais empresa com local definido e responsável por comprar e manter
A47: Área externa - Pracinha é Nossa
A48: -
A49: -
A50: -
A52: Faxina da casa rita toda semana

Sheet Única coisa
A1: Objetivos
A2: Aumentar Ticket +20%
A3: Aumentar ticket 12k
A4: Reduzir custo Oper. -40%
A5: Atender ponta-a-ponta a jornada da Eletromobilidade | B5: Melhorar posicionamento -> Percepção de Valor
A6: MRR Digital + Hard.
A7: Máquina de Indicações e Relacionamento
A9: Serviços de CS
A10: Eletrocalha
A11: Melhorias CDM
A12: Inspeções
A13: Implantação Sist. Carregadores
A14: Botão de Emergência
A16: Plataforma de Gestão de Energia p/ Condomínios
A17: Sistemas e Automações de Processos Internos
A18: Ferramenta Mobile Offline First
A19: Gestão Clickup
... A25: Metas de Novas Receitas -> Plataforma + Hardware + Setup
A26: Setup + obras | B26: Fat. Mensal | C26: 100k
B27: MRR | C27: 10k

Sheet Cronograma PE XPE
A1: Objetivos Principais | D1: Segunda | E1: Terça | F1: Quarta | G1: Quinta | H1: Sexta | J1: Segunda (22)
C2: Manhã | D2: Alinhamento Meta Global 2026. Revisão dos Numeros e Projeção mensal. Considerar calendário, Copa do mundo 26, Eleição, Festividades e Crescimento limitado a geração de Leads. | E2: Fazer o obvio e fácil primeiro. Detalhamento dos resultados mensais comerciais, os objetivos de geração de lead e prever as demandas de projeto. Saber o que será exigido de time e de infraestrutura. Pessoas, material, etc.. Tudo obvio e incluir na projeção com os marcos. O que será feito e quem faz o que? (acho interessante aqui considerar no planejamento exatamente o que temos hoje e o time tech vai justamente viabilizar o resto acontecer. Planejamento financeiro mkt relacionamento, indicações, eventos, salários, melhorias no local, etc... | F2: Terminar o mais importante | G2: Desdobramento Coletivo das Metas | H2: Apresentação do planejamento por área com desdobramento de responsabilidade.
C3: Tarde | D3: Levantamento dos principais desdobramentos estratégicos para alcançar a meta. Alguns: Estratégia de Indicação, Marketing de Relacionamento, Máquina de Indicações. Escalar o operacional com tecnologia (mapear projetos cruciais - App interno, plataforma para clientes, produto específico ger. carregadores, etc...) O que n podemos esquecer: O que precisamos manter? | E3: Fazer o não obvio e mais difícil. Planejamento do crescimento da receita recorrente com novos produtos. Planejamento da parte de obras. Gestão de Pessoas. Novo posicionamento Mídias sociais, rotinas e resultados esperados... | F3: Planejar qual história queremos contar em tudo que fazemos. A missão, o porquê para aumentar o valor percebido em tudo que fazemos e dá direcionamento. "A melhor apresentação" com a melhor intenção e promessa! | G3: Desdobramento Coletivo das Metas | H3: Apresentação do planejamento por área com desdobramento de responsabilidade.
C4: Noite
D5: Não esquecer da única coisa global | E5: Única coisa por área
D8: Lembretes:
D9: Reorganização da Sala - Orçamentos de infraestrutura (climatização, pintura, sala de estar, sala de reunião, copa, etc... Materiais individuais)
D10: Tudo que precisa ser comprado de básico
D11: Quais rotinas de manutenção da ordem? Quais responsabilidades? Limpeza e Condições de Trabalho
D12: Rotina geral da empresa. Primeiro o mais importante: 1ª Segunda-feira do mês: 08h -> Revisão do planejamento estratégico do mês. Planejamento resumido a 1 página com ritos, rotinas, objetivos e responsabilidades
D13: Reunião semanal de abertura e fechamento de semana + PDCA.
D14: Reconhecimentos Mensais, públicos
D15: Reunião de Diretoria invocada sempre que algo está fora do planejamento. Prestar contas, como pedir ajuda e resolver (mínima 30 dias). Não atrapalhar o comercial.

Sheet Sala material
A1: Reforma da sala | B1: Preço | C1: m² | D1: Projeto m² | E1: Qtd peças | F1: Arredondar | G1: Total
A2: Bloco branco diam | B2: 77.81 | C2: =100*0.25*0.25 -> 6.25 | D2: =2.15*(1.15+1.8) -> 6.3425 | E2: =D2/C2 -> 1.0148 | F2: 1 | G2: =F2*B2 -> 77.81 | J2: Estante Led | K2: 6 | L2: 2 | N2: =L2*K2 -> 12
A3: Bloco preto tijolo | B3: =55 -> 55 | C3: =10*0.7*0.77 -> 5.39 | D3: 6.5 | E3: =D3/C3 -> 1.2059369 | F3: 2 | G3: =F3*B3 -> 110 | K3: 2 | L3: 2 | M3: 2 | N3: =SUM(K3:M3) -> 6
A4: Isopor | B4: 100 | C4: =0.5*1 -> 0.5 | D4: 30 | E4: =D4/C4 -> 60 | F4: 60 | G4: =F4*B4 -> 6000 | K4: =2.15*2+5.4 -> 9.7 | L4: =2.15+2.15+2.15+3 -> 9.45 | N4: =L4+K4 -> 19.15
A5: Bloco preto diam | B5: 77.81 | C5: =100*0.25*0.25 -> 6.25 | D5: =2.15*(5.4) -> 11.61 | E5: =D5/C5 -> 1.8576 | F5: 2 | G5: =F5*B5 -> 155.62 | N5: =N4+N3+N2 -> 37.15
A6: Telha zinco | B6: 180 | C6: =3.05*1.1 -> 3.355 | D6: =3.05*2 -> 6.1 | E6: =D6/C6 -> 1.8181818 | F6: 2 | G6: =F6*B6 -> 360
A7: Parede verde | B7: 500 | C7: =25*0.4*0.6 -> 6 | D7: =6*0.6 -> 3.6 | E7: =D7/C7 -> 0.6 | F7: 1 | G7: =F7*B7 -> 500
A8: Estantes | B8: 200 | C8: 1 | D8: 2 | E8: =D8/C8 -> 2 | F8: =E8 -> 2 | G8: =F8*B8 -> 400
A9: Fita led verde | B9: 200 | C9: 1 | D9: 1 | E9: =D9/C9 -> 1 | F9: =E9 -> 1 | G9: =F9*B9 -> 200 | I9: =60*6.4 -> 384
A10: Spot luz 4x | B10: 50 | C10: 2 | D10: 10 | E10: =D10/C10 -> 5 | F10: 5 | G10: =F10*B10 -> 250
A11: Grade preta | B11: 66.9 | C11: =0.3*0.4*10 -> 1.2 | D11: =2.15*(5.4/3) -> 3.87 | E11: =D11/C11 -> 3.225 | F11: 4 | G11: =F11*B11 -> 267.6 | J11: =5.4/3 -> 1.8 | L11: =6*2.8 -> 16.8 | M11: =L11/5.39 -> 3.1168831 | N11: 4*55
A12: Logo 1,20 | B12: 350 | C12: 1 | D12: 1 | E12: =D12/C12 -> 1 | F12: 1 | G12: =F12*B12 -> 350
G13: =SUM(G2:G12) -> 8671.03
B16: 2.1 | C16: 5.12 | D16: =C16*B16 -> 10.752
B17: 2.1 | C17: 5.72 | D17: =C17*B17 -> 12.012
B18: 2.1 | C18: 3.13 | D18: =C18*B18 -> 6.573
