Workbook

Sheet Janeiro26
B1: Igor | F1: Tiago
B2: Tipo | C2: Valor | F2: Tipo | G2: Valor | J2: Total de Reembolso do Mês
B3: Transporte | C3: 429.97 | D3: TRUE | J3: =SUM(C8,G8,G17,C17,C27,G27,C39,G35,K4,K18,K9,C47,G47,C57,G58) -> 5220.93
B4: Alimentação | C4: 133.75 | D4: TRUE | F4: Transporte | H4: FALSE
B5: Almoço Marketing | C5: 101 | D5: TRUE | F5: Alimentação | H5: FALSE
B6: Compra do Pc Biel 2/6 | C6: 379 | D6: TRUE | F6: Crédito no Chip | G6: 30 | H6: TRUE
D7: FALSE | F7: Compra de Ferramentas de Instalação | H7: FALSE
B8: Total | C8: =SUM(C3:C7) -> 1043.72 | D8: TRUE | F8: Total | G8: =SUM(G4:G7) -> 30 | H8: TRUE
B10: Gabriel | F10: Adryan
B11: Tipo | C11: Valor | F11: Tipo | G11: Valor
B12: Transporte/Manutenção | C12: =49.34+51.09 -> 100.43 | D12: TRUE | F12: Transporte | G12: 489.23 | H12: TRUE
B13: Alimentação | C13: =20+25+28 -> 73 | D13: TRUE | F13: Curso Revit 4/12 | G13: 103.11 | H13: TRUE
B14: Plano telefone + Internet chip xpe | C14: 88.88 | D14: TRUE | H14: FALSE
B15: Cadeiras + Microfone 3/14 | C15: 221.44 | D15: TRUE | H15: FALSE
B16: Impressora 3D 1/12 | C16: 284.99 | D16: TRUE | H16: FALSE
B17: Total | C17: =SUM(C12:C16) -> 768.74 | D17: FALSE | F17: Total | G17: =SUM(G12:G16) -> 592.34 | H17: TRUE
B19: Jonildo | F19: Belo
B20: Tipo | C20: Valor | F20: Tipo | G20: Valor
B21: Combustível | C21: 50 | D21: TRUE | F21: Transporte | G21: =15.95+18.95+16.95+14.95+15.93+10.96+8.94+21.98+16.96+14.95 -> 156.52 | H21: TRUE
B22: Alimentação Visitas | D22: FALSE | F22: Alimentação | H22: FALSE
B23: Uber Visitas | C23: 442.16 | D23: TRUE | F23: Crédito no Chip bot | G23: 60 | H23: TRUE
B24: Lojão do condomínio | C24: 45.8 | D24: TRUE | F24: Compra chips desenvolvimento | G24: 90 | H24: TRUE
B25: Curso MUC 10/12 | C25: 99.7 | D25: TRUE | H25: FALSE
B26: ART | D26: FALSE | H26: FALSE
B27: Total | C27: =SUM(C21:C26) -> 637.66 | D27: FALSE | F27: Total | G27: =SUM(G21:G26) -> 306.52 | H27: TRUE
B29: Fernando | F29: Flavio
B30: Tipo | C30: Valor | F30: Tipo | G30: Valor
D31: FALSE | F31: Transporte | H31: FALSE
B32: Transporte/Manutenção | D32: FALSE | F32: gasolina | H32: FALSE
B33: Google Drive | C33: 4.5 | D33: TRUE | F33: Compras de Material office | H33: FALSE
D34: FALSE | F34: almoço | H34: FALSE
B35: Ar Cond 2/12 | C35: 324.95 | D35: TRUE | F35: Total | G35: =SUM(G31:G34) -> 0 | H35: FALSE
B36: Monitores 2/12 | C36: 144.5 | D36: TRUE
B37: Notebooks part 2 - 7/24 | C37: =145.83*2 -> 291.66 | D37: TRUE
B38: notebook estag 2 - 1/12 | C38: 274.91 | D38: FALSE
B39: Total | C39: =SUM(C31:C38) -> 1040.52 | D39: TRUE
B41: Diogo | F41: Decézaris
B42: Tipo | C42: Valor | F42: Tipo | G42: Valor
B43: Transporte | C43: 32.89 | D43: TRUE | F43: Transporte | G43: =21.94+36.96+27.95+21.7+26.96+23.13+26+23.8 -> 208.44 | H43: TRUE
B44: Gás de cozinha | C44: 110 | D44: TRUE | F44: Hospedagem | G44: 0 | H44: FALSE
...

Sheet Cópia de Janeiro26
C1: Igor | H1: Tiago
C2: Tipo | D2: Tipo | E2: Valor | H2: Tipo | I2: Tipo | J2: Valor | M2: Total de Reembolso do Mês
D3: Transporte | E3: 429.97 | F3: TRUE | M3: =SUM(E8,J8,J17,E17,E27,J27,E39,J35,N4,N18,N9,E47,J47,E57,J58) -> 5364.69
D4: Alimentação | E4: 133.75 | F4: TRUE | I4: Transporte | K4: FALSE
D5: Almoço Marketing | E5: 101 | F5: TRUE | I5: Alimentação | K5: FALSE
D6: Compra do Pc Biel 2/6 | E6: 379 | F6: TRUE | I6: Crédito no Chip | J6: 30 | K6: TRUE
F7: FALSE | I7: Compra de Ferramentas de Instalação | K7: FALSE
C8: Total | E8: =SUM(E3:E7) -> 1043.72 | F8: TRUE | H8: Total | J8: =SUM(J4:J7) -> 30 | K8: TRUE
D10: Gabriel | I10: Adryan
D11: Tipo | E11: Valor | I11: Tipo | J11: Valor
D12: Transporte/Manutenção | E12: =49.34+51.09 -> 100.43 | F12: TRUE | I12: Transporte | J12: 489.23 | K12: TRUE
D13: Alimentação | E13: =20+25+28 -> 73 | F13: TRUE | I13: Curso Revit 4/12 | J13: 103.11 | K13: TRUE
D14: Plano telefone + Internet chip xpe | E14: 88.88 | F14: TRUE | K14: FALSE
D15: Cadeiras + Microfone 3/14 | E15: 221.44 | F15: TRUE | K15: FALSE
D16: Impressora 3D 1/12 | E16: 284.99 | F16: TRUE | K16: FALSE
D17: Total | E17: =SUM(E12:E16) -> 768.74 | F17: FALSE | I17: Total | J17: =SUM(J12:J16) -> 592.34 | K17: TRUE
D19: Jonildo | I19: Belo
D20: Tipo | E20: Valor | I20: Tipo | J20: Valor
D21: Combustível | E21: 50 | F21: TRUE | I21: Transporte | J21: =15.95+18.95+16.95+14.95+15.93+10.96+8.94+21.98+16.96+14.95 -> 156.52 | K21: TRUE
D22: Alimentação Visitas | F22: FALSE | I22: Alimentação | K22: FALSE
D23: Uber Visitas | E23: 442.16 | F23: TRUE | I23: Crédito no Chip bot | J23: 60 | K23: TRUE
D24: Lojão do condomínio | E24: 45.8 | F24: TRUE | I24: Compra chips desenvolvimento | J24: 90 | K24: TRUE
D25: Curso MUC 10/12 | E25: 99.7 | F25: TRUE | K25: FALSE
D26: ART | F26: FALSE | K26: FALSE
D27: Total | E27: =SUM(E21:E26) -> 637.66 | F27: FALSE | I27: Total | J27: =SUM(J21:J26) -> 306.52 | K27: TRUE
D29: Fernando | I29: Flavio
D30: Tipo | E30: Valor | I30: Tipo | J30: Valor
F31: FALSE | I31: Transporte | K31: FALSE
D32: Transporte/Manutenção | F32: FALSE | I32: gasolina | K32: FALSE
D33: Google Drive | E33: 4.5 | F33: TRUE | I33: Compras de Material office | K33: FALSE
F34: FALSE | I34: almoço | K34: FALSE
D35: Ar Cond 2/12 | E35: 324.95 | F35: TRUE | I35: Total | J35: =SUM(J31:J34) -> 0 | K35: FALSE
D36: Monitores 2/12 | E36: 144.5 | F36: TRUE
D37: Notebooks part 2 - 7/24 | E37: =145.83*2 -> 291.66 | F37: TRUE
D39: Total | E39: =SUM(E31:E38) -> 765.61 | F39: TRUE
D41: Diogo | I41: Decézaris
D42: Tipo | E42: Valor | I42: Tipo | J42: Valor
D43: Transporte | E43: 32.89 | F43: TRUE | I43: Transporte | J43: =21.94+36.96+27.95+21.7+26.96+23.13+26+23.8 -> 208.44 | K43: TRUE
D44: Gás de cozinha | E44: 110 | F44: TRUE | I44: Hospedagem | J44: 0 | K44: FALSE
D45: alimentação | F45: FALSE | I45: Curso SaaS | J45: 0 | K45: FALSE
...

Sheet Fevereiro26
B1: Igor | F1: Tiago | J1: Total de Reembolso do Mês
B2: Tipo | C2: Valor | F2: Tipo | G2: Valor | J2: =SUM(C8,G8,G17,C17,C27,G27,C37,G35,K4,K18,K9,C47,G47,C57,G58) -> 5543.14
B3: Transporte | C3: =649.55+25.82 -> 675.37 | D3: TRUE
B4: Alimentação | C4: 45.04 | D4: TRUE | F4: Transporte | H4: FALSE
B5: Aniversariante do Mês + Comemorações | C5: =370.78+227.89 -> 598.67 | D5: TRUE | F5: Alimentação | H5: FALSE
B6: Compra do Pc Biel 3/6 | C6: 379 | D6: TRUE | F6: Crédito no Chip | G6: 30 | H6: TRUE
B7: Bomba de Água + pizza | C7: =131.72+152.8 -> 284.52 | D7: TRUE | F7: Compra de Ferramentas de Instalação | H7: FALSE
B8: Total | C8: =SUM(C3:C7) -> 1982.6 | D8: TRUE | F8: Total | G8: =SUM(G4:G7) -> 30 | H8: TRUE
B10: Gabriel | F10: Adryan
B11: Tipo | C11: Valor | F11: Tipo | G11: Valor
B12: Transporte/Manutenção | D12: FALSE | F12: Transporte | G12: =407+15.9+9.9+11.91+11.92+36.96 -> 493.59 | H12: TRUE
B13: Alimentação | D13: FALSE | F13: Curso Revit 5/12 | G13: 103.11 | H13: TRUE
B14: Plano telefone + Internet chip xpe | C14: 88.88 | D14: TRUE | H14: FALSE
B15: Cadeiras + Microfone 4/14 | C15: 221.44 | D15: TRUE | H15: FALSE
B16: Impressora 3D 2/12 | C16: 284.99 | D16: TRUE | H16: FALSE
B17: Total | C17: =SUM(C12:C16) -> 595.31 | D17: TRUE | F17: Total | G17: =SUM(G12:G16) -> 596.7 | H17: TRUE
B19: Jonildo | F19: Belo
B20: Tipo | C20: Valor | F20: Tipo | G20: Valor
B21: Combustível | D21: FALSE | F21: Transporte | G21: =18.95+12.94+15.95+15.98+19.75+12.71+10.49+22.96+20.74+16.88+16.95+15.96 -> 200.26 | H21: TRUE
B22: Alimentação Visitas | D22: FALSE | F22: Alimentação | H22: FALSE
B23: Uber | D23: FALSE | F23: Crédito no Chip bot | G23: 60 | H23: TRUE
B24: Lojão do condomínio | D24: FALSE | H24: FALSE | K24: Fernando
B25: Curso MUC 11/12 | C25: 99.7 | D25: TRUE | H25: FALSE | K25: Tipo | L25: Valor
B26: ART | D26: FALSE | H26: FALSE | K26: Transporte/Manutenção | M26: FALSE
B27: Total | C27: =SUM(C21:C26) -> 99.7 | D27: FALSE | F27: Total | G27: =SUM(G21:G26) -> 260.26 | H27: TRUE | K27: Google Drive | L27: 4.5 | M27: FALSE
K28: Ar Cond 3/12 | L28: 324.95 | M28: FALSE
F29: Flavio | K29: Monitores 3/12 | L29: 144.5 | M29: FALSE
B30: Fernando | F30: Tipo | G30: Valor | K30: Custo de Sala | L30: =145.83*2 -> 291.66 | M30: FALSE
B31: Tipo | C31: Valor | F31: Transporte | G31: =5.53+5.53+6.18+21.94+11.13+11.12+16.96+6.92+6.9 -> 92.21 | H31: TRUE | K31: Total | L31: =SUM(L26:L30) -> 765.61 | M31: TRUE
B32: Transporte/Manutenção | D32: FALSE | F32: gasolina | H32: FALSE
B33: Google Drive | C33: 4.5 | D33: FALSE | F33: Compras de Material leparc | G33: 217.5 | H33: TRUE
B34: Ar Cond 3/12 | C34: 324.95 | D34: FALSE | F34: almoço | H34: FALSE
B35: Monitores 3/12 | C35: 144.5 | D35: FALSE | F35: Total | G35: =SUM(G31:G34) -> 309.71 | H35: FALSE
B36: Notebooks part 2 - 8/24 | C36: =145.83*2 -> 291.66 | D36: FALSE
B37: Total | C37: =SUM(C32:C36) -> 765.61 | D37: TRUE
B41: Diogo | F41: Decézaris
B42: Tipo | C42: Valor | F42: Tipo | G42: Valor
B43: Transporte | C43: 209.99 | D43: TRUE | F43: Transporte | G43: =41.1+35.97+23.76+25 -> 125.83 | H43: TRUE
B44: Gás de cozinha | D44: FALSE | F44: Hospedagem | G44: 0 | H44: FALSE
B45: Alimentação | C45: 110.53 | D45: TRUE | F45: Curso SaaS | G45: 0 | H45: FALSE
...

Sheet Março26
B1: Igor | F1: Tiago | J1: Total de Reembolso do Mês
B2: Tipo | C2: Valor | F2: Tipo | G2: Valor | J2: =SUM(C8,G8,G17,C17,C27,G27,C37,G35,K4,K18,K9,C47,G47,C57,G58) -> 6144.38
B3: Transporte | C3: =505.85+38.16+184.95 -> 728.96 | D3: TRUE
B4: Alimentação | C4: =286.96+123.76 -> 410.72 | D4: TRUE | F4: Transporte | G4: 36.6 | H4: TRUE
B5: Almoço com Cliente | C5: =74 -> 74 | D5: TRUE | F5: Alimentação | H5: FALSE
B6: Compra do Pc Biel 4/6 | C6: 379 | D6: TRUE | F6: Crédito no Chip | G6: 30 | H6: TRUE
B7: Bomba de Água + Brinde obras | C7: =131.72+129.88 -> 261.6 | D7: TRUE | F7: Compra de Ferramentas de Instalação | H7: FALSE
B8: Total | C8: =SUM(C3:C7) -> 1854.28 | D8: TRUE | F8: Total | G8: =SUM(G4:G7) -> 66.6 | H8: TRUE
B10: Gabriel | F10: Adryan
B11: Tipo | C11: Valor | F11: Tipo | G11: Valor
B12: Transporte/Manutenção | C12: 210.97 | D12: FALSE | F12: Transporte | H12: FALSE
B13: Alimentação | D13: FALSE | F13: Curso Revit 6/12 | G13: 103.11 | H13: TRUE
B14: Plano telefone + Internet chip xpe | C14: 88.88 | D14: TRUE | H14: FALSE
B15: Cadeiras + Microfone 5/14 | C15: 221.44 | D15: TRUE | H15: FALSE
B16: Impressora 3D 3/12 | C16: 284.91 | D16: TRUE | H16: FALSE
B17: Total | C17: =SUM(C12:C16) -> 806.2 | D17: TRUE | F17: Total | G17: =SUM(G12:G16) -> 103.11 | H17: TRUE
B19: Jonildo | F19: Belo
B20: Tipo | C20: Valor | F20: Tipo | G20: Valor
B21: Combustível | C21: 40 | D21: TRUE | F21: Transporte | G21: =19.94+14.94+10.94+35.63+18.98+16.98+17.97+17.93+20.94+16.93+18.98+10.35+19.94+10.35 -> 250.8 | H21: TRUE
B22: Alimentação Visitas | D22: FALSE | F22: Alimentação | H22: FALSE
B23: Uber Fev. | C23: 461.42 | D23: TRUE | F23: Crédito no Chip bot | G23: 60 | H23: TRUE
B24: Uber Mar. | C24: 254.77 | D24: TRUE | H24: FALSE
B25: Curso MUC 12/12 | C25: 99.7 | D25: TRUE | H25: FALSE
B26: ART | D26: FALSE | H26: FALSE
B27: Total | C27: =SUM(C21:C26) -> 855.89 | D27: TRUE | F27: Total | G27: =SUM(G21:G26) -> 310.8 | H27: FALSE
B29: Fernando | F29: Flavio
B30: Tipo | C30: Valor | F30: Tipo | G30: Valor
B31: Antropic | C31: =28.19+33.82+28.19+56.38+14.99+57.77+61.4 -> 280.74 | D31: TRUE | F31: Transporte | G31: 297.84 | H31: TRUE
B32: Transporte/Manutenção | D32: FALSE | F32: gasolina | H32: FALSE
B33: Google Drive | C33: 4.5 | D33: TRUE | F33: Compras de Material leparc | H33: FALSE
B34: Ar Cond 4/12 | C34: 324.95 | D34: TRUE | F34: almoço | H34: FALSE
B35: Monitores 4/12 | C35: 144.5 | D35: TRUE | F35: Total | G35: =SUM(G31:G34) -> 297.84 | H35: TRUE
B36: Notebooks part 2 - 9/24 | C36: =145.83*2 -> 291.66 | D36: TRUE
B37: Total | C37: =SUM(C31:C36) -> 1046.35 | D37: TRUE
B41: Diogo | F41: Decézaris
B42: Tipo | C42: Valor | F42: Tipo | G42: Valor
B43: Transporte | C43: 129.14 | D43: TRUE | F43: Transporte | G43: =23.98+22.72+23.21+23.75+20.26+20.25 -> 134.17 | H43: TRUE
B44: Gás de cozinha | D44: FALSE | F44: Hospedagem | G44: 0 | H44: FALSE
B45: Alimentação | D45: FALSE | F45: Curso SaaS | G45: 0 | H45: FALSE
B46: recarga chip | D46: FALSE | H46: FALSE
...

Sheet Abril26
B1: Igor | F1: Tiago | J1: Total de Reembolso do Mês
B2: Tipo | C2: Valor | F2: Tipo | G2: Valor | J2: =SUM(C8,G8,G17,C17,C27,G27,C37,G35,K4,K18,K9,C47,G47,C57,G58) -> 5838.31
B3: Transporte | C3: =694.84+25 -> 719.84 | D3: TRUE
B4: Alimentação | C4: =132.58 -> 132.58 | D4: TRUE | F4: Transporte | H4: FALSE
B5: Almoço com Cliente | D5: FALSE | F5: Alimentação | H5: FALSE
B6: Compra do Pc 5/6 | C6: 379 | D6: TRUE | F6: Crédito no Chip | G6: 30 | H6: FALSE
D7: FALSE | F7: Compra de Ferramentas de Instalação | H7: FALSE
B8: Total | C8: =SUM(C3:C7) -> 1231.42 | D8: TRUE | F8: Total | G8: =SUM(G4:G7) -> 30 | H8: TRUE
B10: Gabriel | F10: Adryan
B11: Tipo | C11: Valor | F11: Tipo | G11: Valor
B12: Transporte/Manutenção | C12: =210.97+39.94+19.97 -> 270.88 | D12: TRUE | F12: Transporte | H12: FALSE
B13: Alimentação | D13: FALSE | F13: Curso Revit 7/12 | G13: 103.11 | H13: TRUE
B14: Plano telefone + Internet chip xpe | C14: 88.88 | D14: TRUE | H14: FALSE
B15: Cadeiras + Microfone 6/14 | C15: 221.44 | D15: TRUE | H15: FALSE
B16: Impressora 3D 4/12 | C16: 284.91 | D16: TRUE | H16: FALSE
B17: Total | C17: =SUM(C12:C16) -> 866.11 | D17: FALSE | F17: Total | G17: =SUM(G12:G16) -> 103.11 | H17: TRUE
B19: Jonildo | F19: Belo
B20: Tipo | C20: Valor | F20: Tipo | G20: Valor
B21: Combustível | D21: FALSE | F21: Transporte | G21: =13.38+23.63+14.96+18.48+13.61 -> 84.06 | H21: TRUE
B22: Alimentação Visitas | D22: FALSE | F22: Alimentação | H22: FALSE
B23: Uber | C23: 721.43 | D23: FALSE | F23: Crédito no Chip bot | G23: 60 | H23: TRUE
B24: Lojão do condomínio | D24: FALSE | H24: FALSE
B25: Curso MUC 12/12 | C25: 99.7 | D25: TRUE | H25: FALSE
B26: ART | C26: =111.38 -> 111.38 | D26: TRUE | H26: FALSE
B27: Total | C27: =SUM(C21:C26) -> 932.51 | D27: FALSE | F27: Total | G27: =SUM(G21:G26) -> 144.06 | H27: TRUE
B29: Fernando | F29: Flavio
B30: Tipo | C30: Valor | F30: Tipo | G30: Valor
B31: Antropic | C31: =28.19+33.82+28.19+56.38+14.99+57.77+61.4 -> 280.74 | D31: TRUE | F31: Transporte | G31: =155.46+48.78 -> 204.24 | H31: TRUE | I31: foi add 48,78 dia 26/06 referente a uber nos dias 29 e 30 (já tinha preenchido o reembolso)
B32: Transporte/Manutenção | D32: FALSE | F32: gasolina | H32: FALSE
B33: Google Drive | C33: 4.5 | D33: TRUE | F33: Compras de Material leparc | H33: FALSE
B34: Ar Cond 5/12 | C34: 324.95 | D34: TRUE | F34: almoço | H34: FALSE
B35: Monitores 5/12 | C35: 144.5 | D35: TRUE | F35: Total | G35: =SUM(G31:G34) -> 204.24 | H35: TRUE
B36: Notebooks part 2 - 10/24 | C36: =145.83*2 -> 291.66 | D36: TRUE
B37: Total | C37: =SUM(C31:C36) -> 1046.35 | D37: TRUE
B41: Diogo | F41: Decézaris
B42: Tipo | C42: Valor | F42: Tipo | G42: Valor
B43: Transporte | C43: 156.1 | D43: TRUE | F43: Transporte | G43: =26.95+22.36+31.1+28.9 -> 109.31 | H43: FALSE
B44: Resmas Folhas | C44: 65.8 | D44: TRUE | F44: Hospedagem | G44: 0 | H44: FALSE
B45: Alimentação | D45: FALSE | F45: Curso SaaS | G45: 0 | H45: FALSE
B46: Cabos e Fita para Inst. | C46: 307.8 | D46: TRUE | H46: FALSE
...

Sheet Maio26
B1: Igor | F1: Tiago | J1: Total de Reembolso do Mês
B2: Tipo | C2: Valor | F2: Tipo | G2: Valor | J2: =SUM(C8,G8,G17,C17,C27,G27,C37,G35,K4,K18,K9,C47,G47,C57,G58,G66,C66) -> 8132.6
B3: Transporte | C3: =596.99+150 -> 746.99 | D3: TRUE
B4: Alimentação | C4: 89.98 | D4: TRUE | F4: Transporte | H4: FALSE
B5: Almoço com Cliente | C5: 170.17 | D5: TRUE | F5: Alimentação | H5: FALSE
B6: Compra do Pc 6/6 | C6: 379 | D6: TRUE | F6: Crédito no Chip | G6: 30 | H6: TRUE
D7: FALSE | F7: Compra de Ferramentas de Instalação | H7: FALSE
B8: Total | C8: =SUM(C3:C7) -> 1386.14 | D8: TRUE | F8: Total | G8: =SUM(G4:G7) -> 30 | H8: TRUE
B10: Gabriel | F10: Adryan
B11: Tipo | C11: Valor | F11: Tipo | G11: Valor | M11: 2100
B12: Transporte/Manutenção | D12: FALSE | F12: Transporte | H12: FALSE | M12: 2500
B13: Alimentação | D13: FALSE | F13: Curso Revit 8/12 | G13: 103.11 | H13: TRUE | M13: 2200
B14: Plano telefone + Internet chip xpe | C14: 88.88 | D14: TRUE | H14: FALSE | M14: 1600
B15: Cadeiras + Microfone 7/14 | C15: 221.44 | D15: TRUE | H15: FALSE
B16: Impressora 3D 5/12 | C16: 284.91 | D16: TRUE | H16: FALSE
B17: Total | C17: =SUM(C12:C16) -> 595.23 | D17: TRUE | F17: Total | G17: =SUM(G12:G16) -> 103.11 | H17: TRUE
B19: Jonildo | F19: Belo
B20: Tipo | C20: Valor | F20: Tipo | G20: Valor
B21: Combustível | C21: 100 | D21: TRUE | F21: Transporte | H21: FALSE
B22: Uber / maio | C22: 640.55 | D22: TRUE | F22: Alimentação | H22: FALSE
B23: Uber / Abril | C23: 721.43 | D23: TRUE | F23: Crédito no Chip bot | G23: 60 | H23: TRUE
B24: Pacotre Office XPE | C24: 599 | D24: TRUE | H24: FALSE
B25: Curso LGR 01/10 | C25: 99.7 | D25: TRUE | H25: FALSE
D26: FALSE | H26: FALSE
B27: Total | C27: =SUM(C21:C26) -> 2160.68 | D27: TRUE | F27: Total | G27: =SUM(G21:G26) -> 60 | H27: TRUE
B29: Fernando | F29: Flavio
B30: Tipo | C30: Valor | F30: Tipo | G30: Valor
B31: notebook estag 2 - 1/12 | C31: 274.91 | D31: TRUE | F31: Transporte | G31: 365.95 | H31: FALSE
B32: Manutenção pcx 50% + bolos e doces | C32: =500/2+75 -> 325 | D32: TRUE | F32: gasolina | H32: FALSE
B33: Google Drive | C33: 4.5 | D33: TRUE | F33: Compras de Material leparc | H33: FALSE
B34: Ar Cond 6/12 | C34: 324.95 | D34: TRUE | F34: almoço | H34: FALSE
B35: Monitores 6/12 | C35: 144.5 | D35: TRUE | F35: Total | G35: =SUM(G31:G34) -> 365.95 | H35: FALSE
B36: Notebooks part 2 - 11/24 | C36: =145.83*2 -> 291.66 | D36: TRUE
B37: Total | C37: =SUM(C31:C36) -> 1365.52 | D37: TRUE
B41: Diogo | F41: Decézaris
B42: Tipo | C42: Valor | F42: Tipo | G42: Valor
B43: Transporte | C43: 712.04 | D43: TRUE | F43: Transporte | G43: =35.94+19.78+31.98+30+35.4+17.4 -> 170.5 | H43: TRUE
B44: Resmas Folhas | D44: FALSE | F44: Hospedagem | G44: 0 | H44: FALSE
B45: Alimentação | D45: FALSE | F45: Notebook parc 2/21 2x* | G45: =157.2*2 -> 314.4 | H45: TRUE
B46: Cabos e Fita para Inst. | D46: FALSE | F46: Monitores + Cadeiras parc 2/12 2x* | G46: =174.67*2 -> 349.34 | H46: TRUE
...

Sheet Junho26
B1: Igor | F1: Tiago | J1: Total de Reembolso do Mês
B2: Tipo | C2: Valor | F2: Tipo | G2: Valor | J2: =SUM(C8,G8,G17,C17,C27,G27,C37,G35,K4,K18,K9,C47,G47,C57,G58,G66,C66) -> 4247.52
B3: Transporte | C3: 813.72 | D3: TRUE
B4: Alimentação | C4: 121.41 | D4: TRUE | F4: Transporte | H4: FALSE
B5: Almoço Obras | C5: 90 | D5: TRUE | F5: Alimentação | H5: FALSE
D6: FALSE | F6: Crédito no Chip | H6: FALSE
D7: FALSE | F7: Compra de Ferramentas de Instalação | H7: FALSE
B8: Total | C8: =SUM(C3:C7) -> 1025.13 | D8: FALSE | F8: Total | G8: =SUM(G4:G7) -> 0 | H8: FALSE
B10: Gabriel | F10: Adryan
B11: Tipo | C11: Valor | F11: Tipo | G11: Valor
B12: Transporte/Manutenção | C12: =10.98+17.9+7.91+52.92+53.86+41.07+42.08+51.95 -> 278.67 | D12: TRUE | F12: Transporte | H12: FALSE
B13: Alimentação | D13: FALSE | F13: Curso Revit 9/12 | G13: 103.11 | H13: TRUE
B14: Plano telefone + Internet chip xpe | C14: 88.88 | D14: TRUE | H14: FALSE
B15: Cadeiras + Microfone 8/14 | C15: 221.44 | D15: TRUE | H15: FALSE
B16: Impressora 3D 6/12 | C16: 284.91 | D16: TRUE | H16: FALSE
B17: Total | C17: =SUM(C12:C16) -> 873.9 | D17: FALSE | F17: Total | G17: =SUM(G12:G16) -> 103.11 | H17: FALSE
B19: Jonildo | F19: Belo
B20: Tipo | C20: Valor | F20: Tipo | G20: Valor
B21: Combustível | D21: FALSE | F21: Transporte | H21: FALSE
B22: Transporte | D22: FALSE | F22: Alimentação | H22: FALSE
D23: FALSE | F23: Crédito no Chip bot | G23: 60 | H23: TRUE
D24: FALSE | H24: FALSE
B25: Curso LGR 02/10 | C25: 99.7 | D25: TRUE | H25: FALSE
D26: FALSE | H26: FALSE
B27: Total | C27: =SUM(C21:C26) -> 99.7 | D27: FALSE | F27: Total | G27: =SUM(G21:G26) -> 60 | H27: FALSE
B29: Fernando | F29: Flavio
B30: Tipo | C30: Valor | F30: Tipo | G30: Valor
B31: notebook estag 2 - 2/12 | C31: 274.91 | D31: TRUE | F31: Transporte | G31: 235.49 | H31: TRUE
D32: FALSE | F32: gasolina | H32: FALSE
B33: Google Drive | C33: 4.5 | D33: TRUE | F33: Compras de Material leparc | H33: FALSE
B34: Ar Cond 7/12 | C34: 324.95 | D34: TRUE | F34: almoço | H34: FALSE
B35: Monitores 7/12 | C35: 144.5 | D35: TRUE | F35: Total | G35: =SUM(G31:G34) -> 235.49 | H35: FALSE
B36: Notebooks part 2 - 12/24 | C36: =145.83*2 -> 291.66 | D36: TRUE
B37: Total | C37: =SUM(C31:C36) -> 1040.52 | D37: TRUE
B41: Diogo | F41: Decézaris
B42: Tipo | C42: Valor | F42: Tipo | G42: Valor
B43: Transporte | D43: FALSE | F43: Transporte | G43: =26.95+26.05+34.3+34.5 -> 121.8 | H43: TRUE
B44: Resmas Folhas | D44: FALSE | F44: Hospedagem | G44: 0 | H44: FALSE
B45: Alimentação | D45: FALSE | F45: Notebook parc 3/21 | G45: =157.2 -> 157.2 | H45: TRUE
B46: Cabos e Fita para Inst. | D46: FALSE | F46: Monitores + Cadeiras parc 3/12 | G46: =174.67 -> 174.67 | H46: TRUE
...

Sheet Julho26
B1: Igor | J1: Total de Reembolso do Mês
B2: Tipo | C2: Valor | F2: Tipo | G2: Valor | J2: =SUM(C8,G8,G18,C18,C28,G28,C40,G36,K4,K19,K9,C50,G50,C60,G61,G69,C69) -> 7193.46
B3: Transporte | C3: =1294.41 -> 1294.41 | D3: TRUE
B4: Alimentação | C4: 368.71 | D4: TRUE | H4: FALSE
D5: FALSE | H5: FALSE
D6: FALSE | H6: FALSE
D7: FALSE | H7: FALSE
B8: Total | C8: =SUM(C3:C7) -> 1663.12 | D8: FALSE | F8: Total | G8: =SUM(G4:G7) -> 0 | H8: FALSE
B10: Gabriel | F10: Adryan
B11: Tipo | C11: Valor | F11: Tipo | G11: Valor
B12: Transporte/Manutenção | D12: FALSE | F12: Transporte | H12: FALSE
B13: Alimentação | D13: FALSE | F13: Curso Revit 10/12 | G13: 103.11 | H13: TRUE
B14: Plano telefone + Internet chip xpe | C14: 88.88 | D14: TRUE | H14: FALSE
B15: Itens Cozinha | C15: =139.9*2 + 27.9*3 -> 363.5 | D15: TRUE | H15: FALSE
B16: Cadeiras + Microfone 9/14 | C16: 221.44 | D16: TRUE | H16: FALSE
B17: Impressora 3D 7/12 | C17: 284.91 | D17: TRUE | H17: FALSE
B18: Total | C18: =SUM(C12:C17) -> 958.73 | D18: FALSE | F18: Total | G18: =SUM(G12:G17) -> 103.11 | H18: FALSE
B20: Jonildo | F20: Belo
B21: Tipo | C21: Valor | F21: Tipo | G21: Valor
B22: Combustível Junho | C22: 50 | D22: TRUE | F22: Transporte | H22: FALSE
B23: Transporte Junho | C23: 716.28 | D23: TRUE | F23: Alimentação | H23: FALSE
B24: Transporte Julho | C24: 195.45 | D24: TRUE | F24: Crédito no Chip bot | G24: 30 | H24: FALSE
D25: FALSE | H25: FALSE
B26: Curso LGR 03/10 | C26: 99.7 | D26: TRUE | H26: FALSE
D27: FALSE | H27: FALSE
B28: Total | C28: =SUM(C22:C27) -> 1061.43 | D28: FALSE | F28: Total | G28: =SUM(G22:G27) -> 30 | H28: FALSE
B30: Fernando | F30: Flavio
B31: Tipo | C31: Valor | F31: Tipo | G31: Valor
B32: notebook estag 2 - 3/12 | C32: 274.91 | D32: TRUE | F32: Transporte | G32: =13.88+11.57+10.46+24.94+30.12+19.68+22.57+13.73+11.81+10.88+6.34+5.83+4.81+10.51+7.37+5.36+5.39+5.23+6.89+4.28+6.25+6.58 -> 244.48 | H32: TRUE
B33: Tv - 1/24 | C33: =108.29 -> 108.29 | D33: TRUE | F33: gasolina | H33: FALSE
B34: Google Drive | C34: 4.5 | D34: TRUE | F34: Compras de Material leparc | H34: FALSE
B35: Ar Cond 8/12 | C35: 324.95 | D35: TRUE | F35: almoço | H35: FALSE
B36: Monitores 8/12 | C36: 144.5 | D36: TRUE | F36: Total | G36: =SUM(G32:G35) -> 244.48 | H36: FALSE
B37: Gela Água - 1/18 | C37: 101.94 | D37: TRUE | H37: FALSE
B38: Pedestal - 1/12 | C38: 30.51 | D38: TRUE | H38: FALSE
B39: Notebooks part 2 - 13/24 | C39: =145.83*2 -> 291.66 | D39: TRUE
B40: Total | C40: =SUM(C32:C39) -> 1281.26 | D40: FALSE
B44: Diogo | F44: Decézaris
B45: Tipo | C45: Valor | F45: Tipo | G45: Valor
B46: Transporte | C46: =10.72+30.91+35.89+13.4+13.64 -> 104.56 | D46: TRUE | F46: Transporte | G46: =25.49+26.32+19.99+25.13 -> 96.93 | H46: TRUE
...

Sheet Reembolso 2026
A1: Mês | B1: Tipo de Reembolso | C1: Igor | D1: Gabriel | E1: Jonildo | F1: Fernando | G1: Diogo | H1: Cleber | I1: Tiago | J1: Adryan | K1: Belo | L1: Flavio | M1: Decézaris | N1: Audrey | O1: Alves
A2: Janeiro | B2: =IFERROR(__xludf.DUMMYFUNCTION("UNIQUE( VSTACK( FILTER( Janeiro26!B1:B988, Janeiro26!B1:B988<>"""", SCAN( 0, Janeiro26!B1:B988, LAMBDA(acc,x, acc + N(LOWER(TRIM(x))=""tipo"") - N(LOWER(TRIM(x))=""total"")) )>0, LOWER(TRIM(Janei"&"ro26!B1:B988))<>""tipo"" ), FILTER( Janeiro26!F1:F988, Janeiro26!F1:F988<>"""", SCAN( 0, Janeiro26!F1:F988, LAMBDA(acc,x, acc + N(LOWER(TRIM(x))=""tipo"") - N(LOWER(TRIM(x))=""total"")) )>0, LO"&"WER(TRIM(Janeiro26!F1:F988))<>""tipo"" ) ) )"),"#REF!") -> #REF! | C2: {=IFNA( LET( colaborador, TRIM(C$1), tipo, TRIM($B2), linhaColab, MATCH(colaborador, Janeiro26!$B:$B, 0), linhaTotal, MATCH("Total", INDEX(Janeiro26!$B:$B, linhaColab+1):Janeiro26!$B:$B, 0) + linhaColab, faixaTipos, INDEX(Janeiro26!$B:$B, linhaColab+2):INDEX(Janeiro26!$B:$B, linhaTotal-1), faixaValores, INDEX(Janeiro26!$C:$C, linhaColab+2):INDEX(Janeiro26!$C:$C, linhaTotal-1), INDEX( faixaValores, MATCH(TRUE, LOWER(TRIM(faixaTipos))=LOWER(tipo), 0) ) ), 0 )} -> 0 | D2: {=IFNA( LET( colaborador, TRIM(D$1), tipo, TRIM($B2), linhaColab, MATCH(colaborador, Janeiro26!$B:$B, 0), linhaTotal, MATCH("Total", INDEX(Janeiro26!$B:$B, linhaColab+1):Janeiro26!$B:$B, 0) + linhaColab, faixaTipos, INDEX(Janeiro26!$B:$B, linhaColab+2):INDEX(Janeiro26!$B:$B, linhaTotal-1), faixaValores, INDEX(Janeiro26!$C:$C, linhaColab+2):INDEX(Janeiro26!$C:$C, linhaTotal-1), INDEX( faixaValores, MATCH(TRUE, LOWER(TRIM(faixaTipos))=LOWER(tipo), 0) ) ), 0 )} -> 0 | E2: {=IFNA( LET( colaborador, TRIM(E$1), tipo, TRIM($B2), linhaColab, MATCH(colaborador, Janeiro26!$B:$B, 0), linhaTotal, MATCH("Total", INDEX(Janeiro26!$B:$B, linhaColab+1):Janeiro26!$B:$B, 0) + linhaColab, faixaTipos, INDEX(Janeiro26!$B:$B, linhaColab+2):INDEX(Janeiro26!$B:$B, linhaTotal-1), faixaValores, INDEX(Janeiro26!$C:$C, linhaColab+2):INDEX(Janeiro26!$C:$C, linhaTotal-1), INDEX( faixaValores, MATCH(TRUE, LOWER(TRIM(faixaTipos))=LOWER(tipo), 0) ) ), 0 )} -> 0 | F2: {=IFNA( LET( colaborador, TRIM(F$1), tipo, TRIM($B2), linhaColab, MATCH(colaborador, Janeiro26!$B:$B, 0), linhaTotal, MATCH("Total", INDEX(Janeiro26!$B:$B, linhaColab+1):Janeiro26!$B:$B, 0) + linhaColab, faixaTipos, INDEX(Janeiro26!$B:$B, linhaColab+2):INDEX(Janeiro26!$B:$B, linhaTotal-1), faixaValores, INDEX(Janeiro26!$C:$C, linhaColab+2):INDEX(Janeiro26!$C:$C, linhaTotal-1), INDEX( faixaValores, MATCH(TRUE, LOWER(TRIM(faixaTipos))=LOWER(tipo), 0) ) ), 0 )} -> 0 | G2: {=IFNA( LET( colaborador, TRIM(G$1), tipo, TRIM($B2), linhaColab, MATCH(colaborador, Janeiro26!$B:$B, 0), linhaTotal, MATCH("Total", INDEX(Janeiro26!$B:$B, linhaColab+1):Janeiro26!$B:$B, 0) + linhaColab, faixaTipos, INDEX(Janeiro26!$B:$B, linhaColab+2):INDEX(Janeiro26!$B:$B, linhaTotal-1), faixaValores, INDEX(Janeiro26!$C:$C, linhaColab+2):INDEX(Janeiro26!$C:$C, linhaTotal-1), INDEX( faixaValores, MATCH(TRUE, LOWER(TRIM(faixaTipos))=LOWER(tipo), 0) ) ), 0 )} -> 0 | H2: {=IFNA( LET( colaborador, TRIM(H$1), tipo, TRIM($B2), linhaColab, MATCH(colaborador, Janeiro26!$B:$B, 0), linhaTotal, MATCH("Total", INDEX(Janeiro26!$B:$B, linhaColab+1):Janeiro26!$B:$B, 0) + linhaColab, faixaTipos, INDEX(Janeiro26!$B:$B, linhaColab+2):INDEX(Janeiro26!$B:$B, linhaTotal-1), faixaValores, INDEX(Janeiro26!$C:$C, linhaColab+2):INDEX(Janeiro26!$C:$C, linhaTotal-1), INDEX( faixaValores, MATCH(TRUE, LOWER(TRIM(faixaTipos))=LOWER(tipo), 0) ) ), 0 )} -> 0 | I2: {=IFNA( LET( colaborador, TRIM(I$1), tipo, TRIM($B2), linhaColab, MATCH(colaborador, Janeiro26!$F:$F, 0), linhaTotal, MATCH("Total", INDEX(Janeiro26!$F:$F, linhaColab+1):Janeiro26!$F:$F, 0) + linhaColab, faixaTipos, INDEX(Janeiro26!$F:$F, linhaColab+2):INDEX(Janeiro26!$F:$F, linhaTotal-1), faixaValores, INDEX(Janeiro26!$G:$G, linhaColab+2):INDEX(Janeiro26!$G:$G, linhaTotal-1), INDEX( faixaValores, MATCH(TRUE, LOWER(TRIM(faixaTipos))=LOWER(tipo), 0) ) ), 0 )} -> 0 | J2: {=IFNA( LET( colaborador, TRIM(J$1), tipo, TRIM($B2), linhaColab, MATCH(colaborador, Janeiro26!$F:$F, 0), linhaTotal, MATCH("Total", INDEX(Janeiro26!$F:$F, linhaColab+1):Janeiro26!$F:$F, 0) + linhaColab, faixaTipos, INDEX(Janeiro26!$F:$F, linhaColab+2):INDEX(Janeiro26!$F:$F, linhaTotal-1), faixaValores, INDEX(Janeiro26!$G:$G, linhaColab+2):INDEX(Janeiro26!$G:$G, linhaTotal-1), INDEX( faixaValores, MATCH(TRUE, LOWER(TRIM(faixaTipos))=LOWER(tipo), 0) ) ), 0 )} -> 0 | K2: {=IFNA( LET( colaborador, TRIM(K$1), tipo, TRIM($B2), linhaColab, MATCH(colaborador, Janeiro26!$F:$F, 0), linhaTotal, MATCH("Total", INDEX(Janeiro26!$F:$F, linhaColab+1):Janeiro26!$F:$F, 0) + linhaColab, faixaTipos, INDEX(Janeiro26!$F:$F, linhaColab+2):INDEX(Janeiro26!$F:$F, linhaTotal-1), faixaValores, INDEX(Janeiro26!$G:$G, linhaColab+2):INDEX(Janeiro26!$G:$G, linhaTotal-1), INDEX( faixaValores, MATCH(TRUE, LOWER(TRIM(faixaTipos))=LOWER(tipo), 0) ) ), 0 )} -> 0 | L2: {=IFNA( LET( colaborador, TRIM(L$1), tipo, TRIM($B2), linhaColab, MATCH(colaborador, Janeiro26!$F:$F, 0), linhaTotal, MATCH("Total", INDEX(Janeiro26!$F:$F, linhaColab+1):Janeiro26!$F:$F, 0) + linhaColab, faixaTipos, INDEX(Janeiro26!$F:$F, linhaColab+2):INDEX(Janeiro26!$F:$F, linhaTotal-1), faixaValores, INDEX(Janeiro26!$G:$G, linhaColab+2):INDEX(Janeiro26!$G:$G, linhaTotal-1), INDEX( faixaValores, MATCH(TRUE, LOWER(TRIM(faixaTipos))=LOWER(tipo), 0) ) ), 0 )} -> 0 | M2: {=IFNA( LET( colaborador, TRIM(M$1), tipo, TRIM($B2), linhaColab, MATCH(colaborador, Janeiro26!$F:$F, 0), linhaTotal, MATCH("Total", INDEX(Janeiro26!$F:$F, linhaColab+1):Janeiro26!$F:$F, 0) + linhaColab, faixaTipos, INDEX(Janeiro26!$F:$F, linhaColab+2):INDEX(Janeiro26!$F:$F, linhaTotal-1), faixaValores, INDEX(Janeiro26!$G:$G, linhaColab+2):INDEX(Janeiro26!$G:$G, linhaTotal-1), INDEX( faixaValores, MATCH(TRUE, LOWER(TRIM(faixaTipos))=LOWER(tipo), 0) ) ), 0 )} -> 0 | N2: {=IFNA( LET( colaborador, TRIM(N$1), tipo, TRIM($B2), linhaColab, MATCH(colaborador, Janeiro26!$F:$F, 0), linhaTotal, MATCH("Total", INDEX(Janeiro26!$F:$F, linhaColab+1):Janeiro26!$F:$F, 0) + linhaColab, faixaTipos, INDEX(Janeiro26!$F:$F, linhaColab+2):INDEX(Janeiro26!$F:$F, linhaTotal-1), faixaValores, INDEX(Janeiro26!$G:$G, linhaColab+2):INDEX(Janeiro26!$G:$G, linhaTotal-1), INDEX( faixaValores, MATCH(TRUE, LOWER(TRIM(faixaTipos))=LOWER(tipo), 0) ) ), 0 )} -> 0 | O2: {=IFNA( LET( colaborador, TRIM(O$1), tipo, TRIM($B2), linhaColab, MATCH(colaborador, Janeiro26!$F:$F, 0), linhaTotal, MATCH("Total", INDEX(Janeiro26!$F:$F, linhaColab+1):Janeiro26!$F:$F, 0) + linhaColab, faixaTipos, INDEX(Janeiro26!$F:$F, linhaColab+2):INDEX(Janeiro26!$F:$F, linhaTotal-1), faixaValores, INDEX(Janeiro26!$G:$G, linhaColab+2):INDEX(Janeiro26!$G:$G, linhaTotal-1), INDEX( faixaValores, MATCH(TRUE, LOWER(TRIM(faixaTipos))=LOWER(tipo), 0) ) ), 0 )} -> 0
A3: Janeiro | C3: {=IFNA( LET( colaborador, TRIM(C$1), tipo, TRIM($B3), linhaColab, MATCH(colaborador, Janeiro26!$B:$B, 0), linhaTotal, MATCH("Total", INDEX(Janeiro26!$B:$B, linhaColab+1):Janeiro26!$B:$B, 0) + linhaColab, faixaTipos, INDEX(Janeiro26!$B:$B, linhaColab+2):INDEX(Janeiro26!$B:$B, linhaTotal-1), faixaValores, INDEX(Janeiro26!$C:$C, linhaColab+2):INDEX(Janeiro26!$C:$C, linhaTotal-1), INDEX( faixaValores, MATCH(TRUE, LOWER(TRIM(faixaTipos))=LOWER(tipo), 0) ) ), 0 )} | D3: {=IFNA( LET( colaborador, TRIM(D$1), tipo, TRIM($B3), linhaColab, MATCH(colaborador, Janeiro26!$B:$B, 0), linhaTotal, MATCH("Total", INDEX(Janeiro26!$B:$B, linhaColab+1):Janeiro26!$B:$B, 0) + linhaColab, faixaTipos, INDEX(Janeiro26!$B:$B, linhaColab+2):INDEX(Janeiro26!$B:$B, linhaTotal-1), faixaValores, INDEX(Janeiro26!$C:$C, linhaColab+2):INDEX(Janeiro26!$C:$C, linhaTotal-1), INDEX( faixaValores, MATCH(TRUE, LOWER(TRIM(faixaTipos))=LOWER(tipo), 0) ) ), 0 )} -> 0 | E3: {=IFNA( LET( colaborador, TRIM(E$1), tipo, TRIM($B3), linhaColab, MATCH(colaborador, Janeiro26!$B:$B, 0), linhaTotal, MATCH("Total", INDEX(Janeiro26!$B:$B, linhaColab+1):Janeiro26!$B:$B, 0) + linhaColab, faixaTipos, INDEX(Janeiro26!$B:$B, linhaColab+2):INDEX(Janeiro26!$B:$B, linhaTotal-1), faixaValores, INDEX(Janeiro26!$C:$C, linhaColab+2):INDEX(Janeiro26!$C:$C, linhaTotal-1), INDEX( faixaValores, MATCH(TRUE, LOWER(TRIM(faixaTipos))=LOWER(tipo), 0) ) ), 0 )} -> 0 | F3: {=IFNA( LET( colaborador, TRIM(F$1), tipo, TRIM($B3), linhaColab, MATCH(colaborador, Janeiro26!$B:$B, 0), linhaTotal, MATCH("Total", INDEX(Janeiro26!$B:$B, linhaColab+1):Janeiro26!$B:$B, 0) + linhaColab, faixaTipos, INDEX(Janeiro26!$B:$B, linhaColab+2):INDEX(Janeiro26!$B:$B, linhaTotal-1), faixaValores, INDEX(Janeiro26!$C:$C, linhaColab+2):INDEX(Janeiro26!$C:$C, linhaTotal-1), INDEX( faixaValores, MATCH(TRUE, LOWER(TRIM(faixaTipos))=LOWER(tipo), 0) ) ), 0 )} | G3: {=IFNA( LET( colaborador, TRIM(G$1), tipo, TRIM($B3), linhaColab, MATCH(colaborador, Janeiro26!$B:$B, 0), linhaTotal, MATCH("Total", INDEX(Janeiro26!$B:$B, linhaColab+1):Janeiro26!$B:$B, 0) + linhaColab, faixaTipos, INDEX(Janeiro26!$B:$B, linhaColab+2):INDEX(Janeiro26!$B:$B, linhaTotal-1), faixaValores, INDEX(Janeiro26!$C:$C, linhaColab+2):INDEX(Janeiro26!$C:$C, linhaTotal-1), INDEX( faixaValores, MATCH(TRUE, LOWER(TRIM(faixaTipos))=LOWER(tipo), 0) ) ), 0 )} | H3: {=IFNA( LET( colaborador, TRIM(H$1), tipo, TRIM($B3), linhaColab, MATCH(colaborador, Janeiro26!$B:$B, 0), linhaTotal, MATCH("Total", INDEX(Janeiro26!$B:$B, linhaColab+1):Janeiro26!$B:$B, 0) + linhaColab, faixaTipos, INDEX(Janeiro26!$B:$B, linhaColab+2):INDEX(Janeiro26!$B:$B, linhaTotal-1), faixaValores, INDEX(Janeiro26!$C:$C, linhaColab+2):INDEX(Janeiro26!$C:$C, linhaTotal-1), INDEX( faixaValores, MATCH(TRUE, LOWER(TRIM(faixaTipos))=LOWER(tipo), 0) ) ), 0 )} | I3: {=IFNA( LET( colaborador, TRIM(I$1), tipo, TRIM($B3), linhaColab, MATCH(colaborador, Janeiro26!$F:$F, 0), linhaTotal, MATCH("Total", INDEX(Janeiro26!$F:$F, linhaColab+1):Janeiro26!$F:$F, 0) + linhaColab, faixaTipos, INDEX(Janeiro26!$F:$F, linhaColab+2):INDEX(Janeiro26!$F:$F, linhaTotal-1), faixaValores, INDEX(Janeiro26!$G:$G, linhaColab+2):INDEX(Janeiro26!$G:$G, linhaTotal-1), INDEX( faixaValores, MATCH(TRUE, LOWER(TRIM(faixaTipos))=LOWER(tipo), 0) ) ), 0 )} | J3: {=IFNA( LET( colaborador, TRIM(J$1), tipo, TRIM($B3), linhaColab, MATCH(colaborador, Janeiro26!$F:$F, 0), linhaTotal, MATCH("Total", INDEX(Janeiro26!$F:$F, linhaColab+1):Janeiro26!$F:$F, 0) + linhaColab, faixaTipos, INDEX(Janeiro26!$F:$F, linhaColab+2):INDEX(Janeiro26!$F:$F, linhaTotal-1), faixaValores, INDEX(Janeiro26!$G:$G, linhaColab+2):INDEX(Janeiro26!$G:$G, linhaTotal-1), INDEX( faixaValores, MATCH(TRUE, LOWER(TRIM(faixaTipos))=LOWER(tipo), 0) ) ), 0 )} | K3: {=IFNA( LET( colaborador, TRIM(K$1), tipo, TRIM($B3), linhaColab, MATCH(colaborador, Janeiro26!$F:$F, 0), linhaTotal, MATCH("Total", INDEX(Janeiro26!$F:$F, linhaColab+1):Janeiro26!$F:$F, 0) + linhaColab, faixaTipos, INDEX(Janeiro26!$F:$F, linhaColab+2):INDEX(Janeiro26!$F:$F, linhaTotal-1), faixaValores, INDEX(Janeiro26!$G:$G, linhaColab+2):INDEX(Janeiro26!$G:$G, linhaTotal-1), INDEX( faixaValores, MATCH(TRUE, LOWER(TRIM(faixaTipos))=LOWER(tipo), 0) ) ), 0 )} | L3: {=IFNA( LET( colaborador, TRIM(L$1), tipo, TRIM($B3), linhaColab, MATCH(colaborador, Janeiro26!$F:$F, 0), linhaTotal, MATCH("Total", INDEX(Janeiro26!$F:$F, linhaColab+1):Janeiro26!$F:$F, 0) + linhaColab, faixaTipos, INDEX(Janeiro26!$F:$F, linhaColab+2):INDEX(Janeiro26!$F:$F, linhaTotal-1), faixaValores, INDEX(Janeiro26!$G:$G, linhaColab+2):INDEX(Janeiro26!$G:$G, linhaTotal-1), INDEX( faixaValores, MATCH(TRUE, LOWER(TRIM(faixaTipos))=LOWER(tipo), 0) ) ), 0 )} | M3: {=IFNA( LET( colaborador, TRIM(M$1), tipo, TRIM($B3), linhaColab, MATCH(colaborador, Janeiro26!$F:$F, 0), linhaTotal, MATCH("Total", INDEX(Janeiro26!$F:$F, linhaColab+1):Janeiro26!$F:$F, 0) + linhaColab, faixaTipos, INDEX(Janeiro26!$F:$F, linhaColab+2):INDEX(Janeiro26!$F:$F, linhaTotal-1), faixaValores, INDEX(Janeiro26!$G:$G, linhaColab+2):INDEX(Janeiro26!$G:$G, linhaTotal-1), INDEX( faixaValores, MATCH(TRUE, LOWER(TRIM(faixaTipos))=LOWER(tipo), 0) ) ), 0 )} | N3: {=IFNA( LET( colaborador, TRIM(N$1), tipo, TRIM($B3), linhaColab, MATCH(colaborador, Janeiro26!$F:$F, 0), linhaTotal, MATCH("Total", INDEX(Janeiro26!$F:$F, linhaColab+1):Janeiro26!$F:$F, 0) + linhaColab, faixaTipos, INDEX(Janeiro26!$F:$F, linhaColab+2):INDEX(Janeiro26!$F:$F, linhaTotal-1), faixaValores, INDEX(Janeiro26!$G:$G, linhaColab+2):INDEX(Janeiro26!$G:$G, linhaTotal-1), INDEX( faixaValores, MATCH(TRUE, LOWER(TRIM(faixaTipos))=LOWER(tipo), 0) ) ), 0 )} | O3: {=IFNA( LET( colaborador, TRIM(O$1), tipo, TRIM($B3), linhaColab, MATCH(colaborador, Janeiro26!$F:$F, 0), linhaTotal, MATCH("Total", INDEX(Janeiro26!$F:$F, linhaColab+1):Janeiro26!$F:$F, 0) + linhaColab, faixaTipos, INDEX(Janeiro26!$F:$F, linhaColab+2):INDEX(Janeiro26!$F:$F, linhaTotal-1), faixaValores, INDEX(Janeiro26!$G:$G, linhaColab+2):INDEX(Janeiro26!$G:$G, linhaTotal-1), INDEX( faixaValores, MATCH(TRUE, LOWER(TRIM(faixaTipos))=LOWER(tipo), 0) ) ), 0 )} -> 0
A4: Janeiro | C4: {=IFNA( LET( colaborador, TRIM(C$1), tipo, TRIM($B4), linhaColab, MATCH(colaborador, Janeiro26!$B:$B, 0), linhaTotal, MATCH("Total", INDEX(Janeiro26!$B:$B, linhaColab+1):Janeiro26!$B:$B, 0) + linhaColab, faixaTipos, INDEX(Janeiro26!$B:$B, linhaColab+2):INDEX(Janeiro26!$B:$B, linhaTotal-1), faixaValores, INDEX(Janeiro26!$C:$C, linhaColab+2):INDEX(Janeiro26!$C:$C, linhaTotal-1), INDEX( faixaValores, MATCH(TRUE, LOWER(TRIM(faixaTipos))=LOWER(tipo), 0) ) ), 0 )} | D4: {=IFNA( LET( colaborador, TRIM(D$1), tipo, TRIM($B4), linhaColab, MATCH(colaborador, Janeiro26!$B:$B, 0), linhaTotal, MATCH("Total", INDEX(Janeiro26!$B:$B, linhaColab+1):Janeiro26!$B:$B, 0) + linhaColab, faixaTipos, INDEX(Janeiro26!$B:$B, linhaColab+2):INDEX(Janeiro26!$B:$B, linhaTotal-1), faixaValores, INDEX(Janeiro26!$C:$C, linhaColab+2):INDEX(Janeiro26!$C:$C, linhaTotal-1), INDEX( faixaValores, MATCH(TRUE, LOWER(TRIM(faixaTipos))=LOWER(tipo), 0) ) ), 0 )} -> 0 | E4: {=IFNA( LET( colaborador, TRIM(E$1), tipo, TRIM($B4), linhaColab, MATCH(colaborador, Janeiro26!$B:$B, 0), linhaTotal, MATCH("Total", INDEX(Janeiro26!$B:$B, linhaColab+1):Janeiro26!$B:$B, 0) + linhaColab, faixaTipos, INDEX(Janeiro26!$B:$B, linhaColab+2):INDEX(Janeiro26!$B:$B, linhaTotal-1), faixaValores, INDEX(Janeiro26!$C:$C, linhaColab+2):INDEX(Janeiro26!$C:$C, linhaTotal-1), INDEX( faixaValores, MATCH(TRUE, LOWER(TRIM(faixaTipos))=LOWER(tipo), 0) ) ), 0 )} -> 0 | F4: {=IFNA( LET( colaborador, TRIM(F$1), tipo, TRIM($B4), linhaColab, MATCH(colaborador, Janeiro26!$B:$B, 0), linhaTotal, MATCH("Total", INDEX(Janeiro26!$B:$B, linhaColab+1):Janeiro26!$B:$B, 0) + linhaColab, faixaTipos, INDEX(Janeiro26!$B:$B, linhaColab+2):INDEX(Janeiro26!$B:$B, linhaTotal-1), faixaValores, INDEX(Janeiro26!$C:$C, linhaColab+2):INDEX(Janeiro26!$C:$C, linhaTotal-1), INDEX( faixaValores, MATCH(TRUE, LOWER(TRIM(faixaTipos))=LOWER(tipo), 0) ) ), 0 )} | G4: {=IFNA( LET( colaborador, TRIM(G$1), tipo, TRIM($B4), linhaColab, MATCH(colaborador, Janeiro26!$B:$B, 0), linhaTotal, MATCH("Total", INDEX(Janeiro26!$B:$B, linhaColab+1):Janeiro26!$B:$B, 0) + linhaColab, faixaTipos, INDEX(Janeiro26!$B:$B, linhaColab+2):INDEX(Janeiro26!$B:$B, linhaTotal-1), faixaValores, INDEX(Janeiro26!$C:$C, linhaColab+2):INDEX(Janeiro26!$C:$C, linhaTotal-1), INDEX( faixaValores, MATCH(TRUE, LOWER(TRIM(faixaTipos))=LOWER(tipo), 0) ) ), 0 )} | H4: {=IFNA( LET( colaborador, TRIM(H$1), tipo, TRIM($B4), linhaColab, MATCH(colaborador, Janeiro26!$B:$B, 0), linhaTotal, MATCH("Total", INDEX(Janeiro26!$B:$B, linhaColab+1):Janeiro26!$B:$B, 0) + linhaColab, faixaTipos, INDEX(Janeiro26!$B:$B, linhaColab+2):INDEX(Janeiro26!$B:$B, linhaTotal-1), faixaValores, INDEX(Janeiro26!$C:$C, linhaColab+2):INDEX(Janeiro26!$C:$C, linhaTotal-1), INDEX( faixaValores, MATCH(TRUE, LOWER(TRIM(faixaTipos))=LOWER(tipo), 0) ) ), 0 )} | I4: {=IFNA( LET( colaborador, TRIM(I$1), tipo, TRIM($B4), linhaColab, MATCH(colaborador, Janeiro26!$F:$F, 0), linhaTotal, MATCH("Total", INDEX(Janeiro26!$F:$F, linhaColab+1):Janeiro26!$F:$F, 0) + linhaColab, faixaTipos, INDEX(Janeiro26!$F:$F, linhaColab+2):INDEX(Janeiro26!$F:$F, linhaTotal-1), faixaValores, INDEX(Janeiro26!$G:$G, linhaColab+2):INDEX(Janeiro26!$G:$G, linhaTotal-1), INDEX( faixaValores, MATCH(TRUE, LOWER(TRIM(faixaTipos))=LOWER(tipo), 0) ) ), 0 )} | J4: {=IFNA( LET( colaborador, TRIM(J$1), tipo, TRIM($B4), linhaColab, MATCH(colaborador, Janeiro26!$F:$F, 0), linhaTotal, MATCH("Total", INDEX(Janeiro26!$F:$F, linhaColab+1):Janeiro26!$F:$F, 0) + linhaColab, faixaTipos, INDEX(Janeiro26!$F:$F, linhaColab+2):INDEX(Janeiro26!$F:$F, linhaTotal-1), faixaValores, INDEX(Janeiro26!$G:$G, linhaColab+2):INDEX(Janeiro26!$G:$G, linhaTotal-1), INDEX( faixaValores, MATCH(TRUE, LOWER(TRIM(faixaTipos))=LOWER(tipo), 0) ) ), 0 )} | K4: {=IFNA( LET( colaborador, TRIM(K$1), tipo, TRIM($B4), linhaColab, MATCH(colaborador, Janeiro26!$F:$F, 0), linhaTotal, MATCH("Total", INDEX(Janeiro26!$F:$F, linhaColab+1):Janeiro26!$F:$F, 0) + linhaColab, faixaTipos, INDEX(Janeiro26!$F:$F, linhaColab+2):INDEX(Janeiro26!$F:$F, linhaTotal-1), faixaValores, INDEX(Janeiro26!$G:$G, linhaColab+2):INDEX(Janeiro26!$G:$G, linhaTotal-1), INDEX( faixaValores, MATCH(TRUE, LOWER(TRIM(faixaTipos))=LOWER(tipo), 0) ) ), 0 )} | L4: {=IFNA( LET( colaborador, TRIM(L$1), tipo, TRIM($B4), linhaColab, MATCH(colaborador, Janeiro26!$F:$F, 0), linhaTotal, MATCH("Total", INDEX(Janeiro26!$F:$F, linhaColab+1):Janeiro26!$F:$F, 0) + linhaColab, faixaTipos, INDEX(Janeiro26!$F:$F, linhaColab+2):INDEX(Janeiro26!$F:$F, linhaTotal-1), faixaValores, INDEX(Janeiro26!$G:$G, linhaColab+2):INDEX(Janeiro26!$G:$G, linhaTotal-1), INDEX( faixaValores, MATCH(TRUE, LOWER(TRIM(faixaTipos))=LOWER(tipo), 0) ) ), 0 )} | M4: {=IFNA( LET( colaborador, TRIM(M$1), tipo, TRIM($B4), linhaColab, MATCH(colaborador, Janeiro26!$F:$F, 0), linhaTotal, MATCH("Total", INDEX(Janeiro26!$F:$F, linhaColab+1):Janeiro26!$F:$F, 0) + linhaColab, faixaTipos, INDEX(Janeiro26!$F:$F, linhaColab+2):INDEX(Janeiro26!$F:$F, linhaTotal-1), faixaValores, INDEX(Janeiro26!$G:$G, linhaColab+2):INDEX(Janeiro26!$G:$G, linhaTotal-1), INDEX( faixaValores, MATCH(TRUE, LOWER(TRIM(faixaTipos))=LOWER(tipo), 0) ) ), 0 )} | N4: {=IFNA( LET( colaborador, TRIM(N$1), tipo, TRIM($B4), linhaColab, MATCH(colaborador, Janeiro26!$F:$F, 0), linhaTotal, MATCH("Total", INDEX(Janeiro26!$F:$F, linhaColab+1):Janeiro26!$F:$F, 0) + linhaColab, faixaTipos, INDEX(Janeiro26!$F:$F, linhaColab+2):INDEX(Janeiro26!$F:$F, linhaTotal-1), faixaValores, INDEX(Janeiro26!$G:$G, linhaColab+2):INDEX(Janeiro26!$G:$G, linhaTotal-1), INDEX( faixaValores, MATCH(TRUE, LOWER(TRIM(faixaTipos))=LOWER(tipo), 0) ) ), 0 )} | O4: {=IFNA( LET( colaborador, TRIM(O$1), tipo, TRIM($B4), linhaColab, MATCH(colaborador, Janeiro26!$F:$F, 0), linhaTotal, MATCH("Total", INDEX(Janeiro26!$F:$F, linhaColab+1):Janeiro26!$F:$F, 0) + linhaColab, faixaTipos, INDEX(Janeiro26!$F:$F, linhaColab+2):INDEX(Janeiro26!$F:$F, linhaTotal-1), faixaValores, INDEX(Janeiro26!$G:$G, linhaColab+2):INDEX(Janeiro26!$G:$G, linhaTotal-1), INDEX( faixaValores, MATCH(TRUE, LOWER(TRIM(faixaTipos))=LOWER(tipo), 0) ) ), 0 )} -> 0
A5: Janeiro | C5: {=IFNA( LET( colaborador, TRIM(C$1), tipo, TRIM($B5), linhaColab, MATCH(colaborador, Janeiro26!$B:$B, 0), linhaTotal, MATCH("Total", INDEX(Janeiro26!$B:$B, linhaColab+1):Janeiro26!$B:$B, 0) + linhaColab, faixaTipos, INDEX(Janeiro26!$B:$B, linhaColab+2):INDEX(Janeiro26!$B:$B, linhaTotal-1), faixaValores, INDEX(Janeiro26!$C:$C, linhaColab+2):INDEX(Janeiro26!$C:$C, linhaTotal-1), INDEX( faixaValores, MATCH(TRUE, LOWER(TRIM(faixaTipos))=LOWER(tipo), 0) ) ), 0 )} | D5: {=IFNA( LET( colaborador, TRIM(D$1), tipo, TRIM($B5), linhaColab, MATCH(colaborador, Janeiro26!$B:$B, 0), linhaTotal, MATCH("Total", INDEX(Janeiro26!$B:$B, linhaColab+1):Janeiro26!$B:$B, 0) + linhaColab, faixaTipos, INDEX(Janeiro26!$B:$B, linhaColab+2):INDEX(Janeiro26!$B:$B, linhaTotal-1), faixaValores, INDEX(Janeiro26!$C:$C, linhaColab+2):INDEX(Janeiro26!$C:$C, linhaTotal-1), INDEX( faixaValores, MATCH(TRUE, LOWER(TRIM(faixaTipos))=LOWER(tipo), 0) ) ), 0 )} -> 0 | E5: {=IFNA( LET( colaborador, TRIM(E$1), tipo, TRIM($B5), linhaColab, MATCH(colaborador, Janeiro26!$B:$B, 0), linhaTotal, MATCH("Total", INDEX(Janeiro26!$B:$B, linhaColab+1):Janeiro26!$B:$B, 0) + linhaColab, faixaTipos, INDEX(Janeiro26!$B:$B, linhaColab+2):INDEX(Janeiro26!$B:$B, linhaTotal-1), faixaValores, INDEX(Janeiro26!$C:$C, linhaColab+2):INDEX(Janeiro26!$C:$C, linhaTotal-1), INDEX( faixaValores, MATCH(TRUE, LOWER(TRIM(faixaTipos))=LOWER(tipo), 0) ) ), 0 )} -> 0 | F5: {=IFNA( LET( colaborador, TRIM(F$1), tipo, TRIM($B5), linhaColab, MATCH(colaborador, Janeiro26!$B:$B, 0), linhaTotal, MATCH("Total", INDEX(Janeiro26!$B:$B, linhaColab+1):Janeiro26!$B:$B, 0) + linhaColab, faixaTipos, INDEX(Janeiro26!$B:$B, linhaColab+2):INDEX(Janeiro26!$B:$B, linhaTotal-1), faixaValores, INDEX(Janeiro26!$C:$C, linhaColab+2):INDEX(Janeiro26!$C:$C, linhaTotal-1), INDEX( faixaValores, MATCH(TRUE, LOWER(TRIM(faixaTipos))=LOWER(tipo), 0) ) ), 0 )} | G5: {=IFNA( LET( colaborador, TRIM(G$1), tipo, TRIM($B5), linhaColab, MATCH(colaborador, Janeiro26!$B:$B, 0), linhaTotal, MATCH("Total", INDEX(Janeiro26!$B:$B, linhaColab+1):Janeiro26!$B:$B, 0) + linhaColab, faixaTipos, INDEX(Janeiro26!$B:$B, linhaColab+2):INDEX(Janeiro26!$B:$B, linhaTotal-1), faixaValores, INDEX(Janeiro26!$C:$C, linhaColab+2):INDEX(Janeiro26!$C:$C, linhaTotal-1), INDEX( faixaValores, MATCH(TRUE, LOWER(TRIM(faixaTipos))=LOWER(tipo), 0) ) ), 0 )} | H5: {=IFNA( LET( colaborador, TRIM(H$1), tipo, TRIM($B5), linhaColab, MATCH(colaborador, Janeiro26!$B:$B, 0), linhaTotal, MATCH("Total", INDEX(Janeiro26!$B:$B, linhaColab+1):Janeiro26!$B:$B, 0) + linhaColab, faixaTipos, INDEX(Janeiro26!$B:$B, linhaColab+2):INDEX(Janeiro26!$B:$B, linhaTotal-1), faixaValores, INDEX(Janeiro26!$C:$C, linhaColab+2):INDEX(Janeiro26!$C:$C, linhaTotal-1), INDEX( faixaValores, MATCH(TRUE, LOWER(TRIM(faixaTipos))=LOWER(tipo), 0) ) ), 0 )} | I5: {=IFNA( LET( colaborador, TRIM(I$1), tipo, TRIM($B5), linhaColab, MATCH(colaborador, Janeiro26!$F:$F, 0), linhaTotal, MATCH("Total", INDEX(Janeiro26!$F:$F, linhaColab+1):Janeiro26!$F:$F, 0) + linhaColab, faixaTipos, INDEX(Janeiro26!$F:$F, linhaColab+2):INDEX(Janeiro26!$F:$F, linhaTotal-1), faixaValores, INDEX(Janeiro26!$G:$G, linhaColab+2):INDEX(Janeiro26!$G:$G, linhaTotal-1), INDEX( faixaValores, MATCH(TRUE, LOWER(TRIM(faixaTipos))=LOWER(tipo), 0) ) ), 0 )} | J5: {=IFNA( LET( colaborador, TRIM(J$1), tipo, TRIM($B5), linhaColab, MATCH(colaborador, Janeiro26!$F:$F, 0), linhaTotal, MATCH("Total", INDEX(Janeiro26!$F:$F, linhaColab+1):Janeiro26!$F:$F, 0) + linhaColab, faixaTipos, INDEX(Janeiro26!$F:$F, linhaColab+2):INDEX(Janeiro26!$F:$F, linhaTotal-1), faixaValores, INDEX(Janeiro26!$G:$G, linhaColab+2):INDEX(Janeiro26!$G:$G, linhaTotal-1), INDEX( faixaValores, MATCH(TRUE, LOWER(TRIM(faixaTipos))=LOWER(tipo), 0) ) ), 0 )} | K5: {=IFNA( LET( colaborador, TRIM(K$1), tipo, TRIM($B5), linhaColab, MATCH(colaborador, Janeiro26!$F:$F, 0), linhaTotal, MATCH("Total", INDEX(Janeiro26!$F:$F, linhaColab+1):Janeiro26!$F:$F, 0) + linhaColab, faixaTipos, INDEX(Janeiro26!$F:$F, linhaColab+2):INDEX(Janeiro26!$F:$F, linhaTotal-1), faixaValores, INDEX(Janeiro26!$G:$G, linhaColab+2):INDEX(Janeiro26!$G:$G, linhaTotal-1), INDEX( faixaValores, MATCH(TRUE, LOWER(TRIM(faixaTipos))=LOWER(tipo), 0) ) ), 0 )} | L5: {=IFNA( LET( colaborador, TRIM(L$1), tipo, TRIM($B5), linhaColab, MATCH(colaborador, Janeiro26!$F:$F, 0), linhaTotal, MATCH("Total", INDEX(Janeiro26!$F:$F, linhaColab+1):Janeiro26!$F:$F, 0) + linhaColab, faixaTipos, INDEX(Janeiro26!$F:$F, linhaColab+2):INDEX(Janeiro26!$F:$F, linhaTotal-1), faixaValores, INDEX(Janeiro26!$G:$G, linhaColab+2):INDEX(Janeiro26!$G:$G, linhaTotal-1), INDEX( faixaValores, MATCH(TRUE, LOWER(TRIM(faixaTipos))=LOWER(tipo), 0) ) ), 0 )} | M5: {=IFNA( LET( colaborador, TRIM(M$1), tipo, TRIM($B5), linhaColab, MATCH(colaborador, Janeiro26!$F:$F, 0), linhaTotal, MATCH("Total", INDEX(Janeiro26!$F:$F, linhaColab+1):Janeiro26!$F:$F, 0) + linhaColab, faixaTipos, INDEX(Janeiro26!$F:$F, linhaColab+2):INDEX(Janeiro26!$F:$F, linhaTotal-1), faixaValores, INDEX(Janeiro26!$G:$G, linhaColab+2):INDEX(Janeiro26!$G:$G, linhaTotal-1), INDEX( faixaValores, MATCH(TRUE, LOWER(TRIM(faixaTipos))=LOWER(tipo), 0) ) ), 0 )} | N5: {=IFNA( LET( colaborador, TRIM(N$1), tipo, TRIM($B5), linhaColab, MATCH(colaborador, Janeiro26!$F:$F, 0), linhaTotal, MATCH("Total", INDEX(Janeiro26!$F:$F, linhaColab+1):Janeiro26!$F:$F, 0) + linhaColab, faixaTipos, INDEX(Janeiro26!$F:$F, linhaColab+2):INDEX(Janeiro26!$F:$F, linhaTotal-1), faixaValores, INDEX(Janeiro26!$G:$G, linhaColab+2):INDEX(Janeiro26!$G:$G, linhaTotal-1), INDEX( faixaValores, MATCH(TRUE, LOWER(TRIM(faixaTipos))=LOWER(tipo), 0) ) ), 0 )} | O5: {=IFNA( LET( colaborador, TRIM(O$1), tipo, TRIM($B5), linhaColab, MATCH(colaborador, Janeiro26!$F:$F, 0), linhaTotal, MATCH("Total", INDEX(Janeiro26!$F:$F, linhaColab+1):Janeiro26!$F:$F, 0) + linhaColab, faixaTipos, INDEX(Janeiro26!$F:$F, linhaColab+2):INDEX(Janeiro26!$F:$F, linhaTotal-1), faixaValores, INDEX(Janeiro26!$G:$G, linhaColab+2):INDEX(Janeiro26!$G:$G, linhaTotal-1), INDEX( faixaValores, MATCH(TRUE, LOWER(TRIM(faixaTipos))=LOWER(tipo), 0) ) ), 0 )} -> 0
A6: Janeiro | C6: {=IFNA( LET( colaborador, TRIM(C$1), tipo, TRIM($B6), linhaColab, MATCH(colaborador, Janeiro26!$B:$B, 0), linhaTotal, MATCH("Total", INDEX(Janeiro26!$B:$B, linhaColab+1):Janeiro26!$B:$B, 0) + linhaColab, faixaTipos, INDEX(Janeiro26!$B:$B, linhaColab+2):INDEX(Janeiro26!$B:$B, linhaTotal-1), faixaValores, INDEX(Janeiro26!$C:$C, linhaColab+2):INDEX(Janeiro26!$C:$C, linhaTotal-1), INDEX( faixaValores, MATCH(TRUE, LOWER(TRIM(faixaTipos))=LOWER(tipo), 0) ) ), 0 )} | D6: {=IFNA( LET( colaborador, TRIM(D$1), tipo, TRIM($B6), linhaColab, MATCH(colaborador, Janeiro26!$B:$B, 0), linhaTotal, MATCH("Total", INDEX(Janeiro26!$B:$B, linhaColab+1):Janeiro26!$B:$B, 0) + linhaColab, faixaTipos, INDEX(Janeiro26!$B:$B, linhaColab+2):INDEX(Janeiro26!$B:$B, linhaTotal-1), faixaValores, INDEX(Janeiro26!$C:$C, linhaColab+2):INDEX(Janeiro26!$C:$C, linhaTotal-1), INDEX( faixaValores, MATCH(TRUE, LOWER(TRIM(faixaTipos))=LOWER(tipo), 0) ) ), 0 )} -> 0 | E6: {=IFNA( LET( colaborador, TRIM(E$1), tipo, TRIM($B6), linhaColab, MATCH(colaborador, Janeiro26!$B:$B, 0), linhaTotal, MATCH("Total", INDEX(Janeiro26!$B:$B, linhaColab+1):Janeiro26!$B:$B, 0) + linhaColab, faixaTipos, INDEX(Janeiro26!$B:$B, linhaColab+2):INDEX(Janeiro26!$B:$B, linhaTotal-1), faixaValores, INDEX(Janeiro26!$C:$C, linhaColab+2):INDEX(Janeiro26!$C:$C, linhaTotal-1), INDEX( faixaValores, MATCH(TRUE, LOWER(TRIM(faixaTipos))=LOWER(tipo), 0) ) ), 0 )} -> 0 | F6: {=IFNA( LET( colaborador, TRIM(F$1), tipo, TRIM($B6), linhaColab, MATCH(colaborador, Janeiro26!$B:$B, 0), linhaTotal, MATCH("Total", INDEX(Janeiro26!$B:$B, linhaColab+1):Janeiro26!$B:$B, 0) + linhaColab, faixaTipos, INDEX(Janeiro26!$B:$B, linhaColab+2):INDEX(Janeiro26!$B:$B, linhaTotal-1), faixaValores, INDEX(Janeiro26!$C:$C, linhaColab+2):INDEX(Janeiro26!$C:$C, linhaTotal-1), INDEX( faixaValores, MATCH(TRUE, LOWER(TRIM(faixaTipos))=LOWER(tipo), 0) ) ), 0 )} | G6: {=IFNA( LET( colaborador, TRIM(G$1), tipo, TRIM($B6), linhaColab, MATCH(colaborador, Janeiro26!$B:$B, 0), linhaTotal, MATCH("Total", INDEX(Janeiro26!$B:$B, linhaColab+1):Janeiro26!$B:$B, 0) + linhaColab, faixaTipos, INDEX(Janeiro26!$B:$B, linhaColab+2):INDEX(Janeiro26!$B:$B, linhaTotal-1), faixaValores, INDEX(Janeiro26!$C:$C, linhaColab+2):INDEX(Janeiro26!$C:$C, linhaTotal-1), INDEX( faixaValores, MATCH(TRUE, LOWER(TRIM(faixaTipos))=LOWER(tipo), 0) ) ), 0 )} | H6: {=IFNA( LET( colaborador, TRIM(H$1), tipo, TRIM($B6), linhaColab, MATCH(colaborador, Janeiro26!$B:$B, 0), linhaTotal, MATCH("Total", INDEX(Janeiro26!$B:$B, linhaColab+1):Janeiro26!$B:$B, 0) + linhaColab, faixaTipos, INDEX(Janeiro26!$B:$B, linhaColab+2):INDEX(Janeiro26!$B:$B, linhaTotal-1), faixaValores, INDEX(Janeiro26!$C:$C, linhaColab+2):INDEX(Janeiro26!$C:$C, linhaTotal-1), INDEX( faixaValores, MATCH(TRUE, LOWER(TRIM(faixaTipos))=LOWER(tipo), 0) ) ), 0 )} | I6: {=IFNA( LET( colaborador, TRIM(I$1), tipo, TRIM($B6), linhaColab, MATCH(colaborador, Janeiro26!$F:$F, 0), linhaTotal, MATCH("Total", INDEX(Janeiro26!$F:$F, linhaColab+1):Janeiro26!$F:$F, 0) + linhaColab, faixaTipos, INDEX(Janeiro26!$F:$F, linhaColab+2):INDEX(Janeiro26!$F:$F, linhaTotal-1), faixaValores, INDEX(Janeiro26!$G:$G, linhaColab+2):INDEX(Janeiro26!$G:$G, linhaTotal-1), INDEX( faixaValores, MATCH(TRUE, LOWER(TRIM(faixaTipos))=LOWER(tipo), 0) ) ), 0 )} | J6: {=IFNA( LET( colaborador, TRIM(J$1), tipo, TRIM($B6), linhaColab, MATCH(colaborador, Janeiro26!$F:$F, 0), linhaTotal, MATCH("Total", INDEX(Janeiro26!$F:$F, linhaColab+1):Janeiro26!$F:$F, 0) + linhaColab, faixaTipos, INDEX(Janeiro26!$F:$F, linhaColab+2):INDEX(Janeiro26!$F:$F, linhaTotal-1), faixaValores, INDEX(Janeiro26!$G:$G, linhaColab+2):INDEX(Janeiro26!$G:$G, linhaTotal-1), INDEX( faixaValores, MATCH(TRUE, LOWER(TRIM(faixaTipos))=LOWER(tipo), 0) ) ), 0 )} | K6: {=IFNA( LET( colaborador, TRIM(K$1), tipo, TRIM($B6), linhaColab, MATCH(colaborador, Janeiro26!$F:$F, 0), linhaTotal, MATCH("Total", INDEX(Janeiro26!$F:$F, linhaColab+1):Janeiro26!$F:$F, 0) + linhaColab, faixaTipos, INDEX(Janeiro26!$F:$F, linhaColab+2):INDEX(Janeiro26!$F:$F, linhaTotal-1), faixaValores, INDEX(Janeiro26!$G:$G, linhaColab+2):INDEX(Janeiro26!$G:$G, linhaTotal-1), INDEX( faixaValores, MATCH(TRUE, LOWER(TRIM(faixaTipos))=LOWER(tipo), 0) ) ), 0 )} | L6: {=IFNA( LET( colaborador, TRIM(L$1), tipo, TRIM($B6), linhaColab, MATCH(colaborador, Janeiro26!$F:$F, 0), linhaTotal, MATCH("Total", INDEX(Janeiro26!$F:$F, linhaColab+1):Janeiro26!$F:$F, 0) + linhaColab, faixaTipos, INDEX(Janeiro26!$F:$F, linhaColab+2):INDEX(Janeiro26!$F:$F, linhaTotal-1), faixaValores, INDEX(Janeiro26!$G:$G, linhaColab+2):INDEX(Janeiro26!$G:$G, linhaTotal-1), INDEX( faixaValores, MATCH(TRUE, LOWER(TRIM(faixaTipos))=LOWER(tipo), 0) ) ), 0 )} | M6: {=IFNA( LET( colaborador, TRIM(M$1), tipo, TRIM($B6), linhaColab, MATCH(colaborador, Janeiro26!$F:$F, 0), linhaTotal, MATCH("Total", INDEX(Janeiro26!$F:$F, linhaColab+1):Janeiro26!$F:$F, 0) + linhaColab, faixaTipos, INDEX(Janeiro26!$F:$F, linhaColab+2):INDEX(Janeiro26!$F:$F, linhaTotal-1), faixaValores, INDEX(Janeiro26!$G:$G, linhaColab+2):INDEX(Janeiro26!$G:$G, linhaTotal-1), INDEX( faixaValores, MATCH(TRUE, LOWER(TRIM(faixaTipos))=LOWER(tipo), 0) ) ), 0 )} | N6: {=IFNA( LET( colaborador, TRIM(N$1), tipo, TRIM($B6), linhaColab, MATCH(colaborador, Janeiro26!$F:$F, 0), linhaTotal, MATCH("Total", INDEX(Janeiro26!$F:$F, linhaColab+1):Janeiro26!$F:$F, 0) + linhaColab, faixaTipos, INDEX(Janeiro26!$F:$F, linhaColab+2):INDEX(Janeiro26!$F:$F, linhaTotal-1), faixaValores, INDEX(Janeiro26!$G:$G, linhaColab+2):INDEX(Janeiro26!$G:$G, linhaTotal-1), INDEX( faixaValores, MATCH(TRUE, LOWER(TRIM(faixaTipos))=LOWER(tipo), 0) ) ), 0 )} | O6: {=IFNA( LET( colaborador, TRIM(O$1), tipo, TRIM($B6), linhaColab, MATCH(colaborador, Janeiro26!$F:$F, 0), linhaTotal, MATCH("Total", INDEX(Janeiro26!$F:$F, linhaColab+1):Janeiro26!$F:$F, 0) + linhaColab, faixaTipos, INDEX(Janeiro26!$F:$F, linhaColab+2):INDEX(Janeiro26!$F:$F, linhaTotal-1), faixaValores, INDEX(Janeiro26!$G:$G, linhaColab+2):INDEX(Janeiro26!$G:$G, linhaTotal-1), INDEX( faixaValores, MATCH(TRUE, LOWER(TRIM(faixaTipos))=LOWER(tipo), 0) ) ), 0 )} -> 0
